Workbook

Sheet Capital de Trabajo
B5: Grupo Xanalab
B6: Al 30 de Junio del 2025
B7: Analisis Financiero de Capital de Trabajo
B10: Activos | G10: MXN | I10: Fuentes de Recursos | O10: MXN
B12: Detalle de Cuentas por Cobrar | I12: Detalle de Cuentas por Pagar Operativas
B14: *** Detalle de principales clientes | I14: *** Detalle de principales proveedores
B20: Total de Cuentas por Cobrar | G20: 41982958 | I20: Total de Cuentas por Pagar Operativas | O20: 16383076
B22: Detalle de Inventario | I22: Detalle de Cuentas por Pagar Contigentes y NO Operativas
B24: Materia prima | I24: *** Detalle de principales contingencias a cargo y cuentas no operativas por pagar.
B25: Producto terminado
B26: Empaque
B27: Otros
B29: Total de Inventarios | G29: 28209330 | I29: Total de Cuentas por Pagar Contingentes y NO Operativas | O29: 16500000
B31: Detalle de Activos Fijos | I31: Detalle de Cuentas por Pagar entre Partes Relacionadas
I32: IVA
B33: Terrenos
B34: Edificios
B35: Maquinaria y equipo
B36: Equipo de Transporte
B37: Mobiliario y equipo
B39: Total de Activos Fijos | G39: 46811280 | I39: Total de Cuentas por Pagar a Partes Relacionadas | O39: =+SUM(O31:O38) -> 0
B41: Detalle de Arrendamientos | I41: Detalle de Deuda con Costo (Créditos Bancarios y Arrendamientos)
B43: Terrenos en Arrendamiento | I43: Capital X
B44: Edificios en Arrendamiento | I44: Santander
B45: Maquinaria y equipo en Arrendamiento | I45: Banregio
B46: Equipo de Transporte en Arrendamiento | I46: Capix
B47: Mobiliario y equipo en Arrendamiento
B49: Total de Arrendamientos | G49: 15643526 | I49: Total de Deuda | O49: 84288718
B51: Detalle de Intangibles | I51: Detalle de Capital
B53: Marca Biomiral | I53: *** Detalle de deuda convertida en acciones en favor de NUVARI
B54: Marcas - otras
B55: Marcas - otras
B56: Licencias COFEPRIS
B57: Licencias Otras
B59: Total de Intangibles | G59: 24000000 | I59: Total de Capital | O59: 64500000
B61: Total de Activos | F61: ∑ | G61: =+G59+G49+G39+G29+G20 -> 1.5664709e+08 | I61: Total de Pasivos y Capital | N61: ∑ | O61: =+O59+O49+O39+O29+O20 -> 1.8167179e+08
B65: Capital de Trabajo Neto | F65: ∑ | G65: =+G61-O61 -> -25024700

Sheet Flujo
B5: Grupo Xanalab
B6: Al 30 de Junio del 2025
B7: Flujo
G9: 2025 | I9: 2026 | K9: 2027
B10: Detalle | G10: MXN | I10: MXN | K10: MXN
B12: EBITDA | G12: =+SUM('IS (ROLLING)'!P61:AA61) -> 19665572 | I12: =+'IS (ROLLING)'!AP61 -> 55133517 | K12: =+'IS (ROLLING)'!BD61 -> 85011815
A14: (-) | B14: Gastos Financieros | G14: ='IS (ROLLING)'!AB64 -> 14822493 | I14: ='IS (ROLLING)'!AP64 -> 16508198 | K14: ='IS (ROLLING)'!BD64 -> 7363493.7
A15: (-) | B15: Impuestos
A16: (-) | B16: Capital Expenditure (CapEx) | G16: ='Cashflow (ROLLING) CAP'!N36 -> 5100000 | I16: ='Cashflow (ROLLING) CAP'!AA36 -> 9000000 | K16: ='Cashflow (ROLLING) CAP'!AN36 -> 3600000
A17: (-) | B17: Pago Créditos Bancarios | G17: =SUM('Cashflow (ROLLING) CAP'!N48:N52) -> 45483744 | I17: =SUM('Cashflow (ROLLING) CAP'!AA48:AA52) -> 21061379 | K17: =SUM('Cashflow (ROLLING) CAP'!AN48:AN52) -> 14157784
A18: (-) | B18: Pago de Arrendamientos | G18: =SUM('Cashflow (ROLLING) CAP'!N53:N54) -> 3891757.7 | I18: ='Cashflow (ROLLING) CAP'!AA54 -> 3694116.4 | K18: ='Cashflow (ROLLING) CAP'!AN54 -> 3529152.9
A19: (-) | B19: Pago de Contigencias (Impuestos+Actualizciones y Recargos) | G19: ='Cashflow (ROLLING) CAP'!N47 -> 7500000 | I19: ='Cashflow (ROLLING) CAP'!AA47 -> 7500000 | K19: ='Cashflow (ROLLING) CAP'!AN47 -> 0
A20: (-) | B20: Pago de Contigencias (Otros) | G20: ='Cashflow (ROLLING) CAP'!N37 -> 650000 | I20: ='Cashflow (ROLLING) CAP'!AA37 -> 300000 | K20: ='Cashflow (ROLLING) CAP'!AN37 -> 0
B22: Free Cash Flow (FCF) | G22: =+G12-SUM(G14:G20) -> -57782422 | I22: =+I12-SUM(I14:I20) -> -2930176.9 | K22: =+K12-SUM(K14:K20) -> 56361384

Sheet 1Q Consolidado
A1: Xana Lab SA de CV - Farmiral SA de CV | K1: Xana Lab SA de CV - Farmiral SA de CV | Q1: Xana Lab SA de CV - Farmiral SA de CV | W1: Xana Lab SA de CV - Farmiral SA de CV
A2: Estado de Resultados por mes de enero a marzo 2025 | K2: Estado de Resultados del 01 al 31de Enero 2025 | Q2: Estado de Resultados del 01 al 28 de Febrero 2025 | W2: Estado de Resultados del 01 al 31 de Marzo 2025
B4: Periodo | C4: % | D4: Periodo | E4: % | F4: Periodo | G4: % | H4: Acumulado | I4: % | L4: Periodo | M4: % | N4: Acumulado | O4: % | R4: Periodo | S4: % | T4: Acumulado | U4: % | X4: Periodo | Y4: % | Z4: Acumulado | AA4: %
A6: I n g r e s o s | B6: ENERO | D6: FEBRERO | F6: MARZO | H6: ENERO A MARZO | K6: I n g r e s o s | Q6: I n g r e s o s | W6: I n g r e s o s
A8: Ventas de producto grav a tasa gral | K8: Ventas de producto grav a tasa gral | Q8: Ventas de producto grav a tasa gral | W8: Ventas de producto grav a tasa gral
A9: Maquila | B9: 10514791 | C9: 67.199073 | D9: 8719963 | E9: 56.322545 | F9: 5524668.5 | G9: 46.018346 | H9: 24759422 | I9: 57.400141 | K9: Maquila | L9: 10514791 | M9: 67.199073 | N9: 10514791 | O9: 67.199073 | Q9: Maquila | R9: 8719963 | S9: 56.322545 | T9: 19234754 | U9: 61.789641 | W9: Maquila | X9: 5524668.5 | Y9: 46.018346 | Z9: 24759422 | AA9: 57.400141
A10: Marca Propia | B10: 795925.39 | C10: 5.0866869 | D10: 4286349.3 | E10: 27.68568 | F10: 5389707.1 | G10: 44.89417 | H10: 10388496 | I10: 24.083806 | K10: Marca Propia | L10: 795925.39 | M10: 5.0866869 | N10: 795925.39 | O10: 5.0866869 | Q10: Marca Propia | R10: 4286349.3 | S10: 27.68568 | T10: 5082274.7 | U10: 16.326278 | W10: Marca Propia | X10: 5389707.1 | Y10: 44.89417 | Z10: 10388496 | AA10: 24.083806
A11: Biomiral | K11: Biomiral | Q11: Biomiral | W11: Biomiral | Z11: 0
A12: Distribuidores | B12: 5007487.3 | C12: 32.002397 | D12: 2933807.5 | E12: 18.949565 | F12: 2082595.7 | G12: 17.347214 | H12: 10023891 | I12: 23.238536 | K12: Distribuidores | L12: 5007487.3 | M12: 32.002397 | N12: 5007487.3 | O12: 32.002397 | Q12: Distribuidores | R12: 2933807.5 | S12: 18.949565 | T12: 7941294.8 | U12: 25.510582 | W12: Distribuidores | X12: 2082595.7 | Y12: 17.347214 | Z12: 10023891 | AA12: 23.238536
A13: Retail | B13: 612222.09 | C13: 3.9126558 | D13: 58624.64 | E13: 0.3786586 | F13: 105829.02 | G13: 0.88151469 | H13: 776393.02 | I13: 1.7999236 | K13: Retail | L13: 612222.09 | M13: 3.9126558 | N13: 612222.09 | O13: 3.9126558 | Q13: Retail | R13: 58624.64 | S13: 0.3786586 | T13: 670846.73 | U13: 2.1550252 | W13: Retail | X13: 105829.02 | Y13: 0.88151469 | Z13: 776393.02 | AA13: 1.7999236
A15: Total Biomiral | B15: 5619709.4 | C15: 35.915053 | D15: 2992432.2 | E15: 19.328224 | F15: 2188424.7 | G15: 18.228729 | H15: 10800284 | I15: 25.03846 | K15: Total Biomiral | L15: 5619709.4 | M15: 35.915053 | N15: 5619709.4 | O15: 35.915053 | Q15: Total Biomiral | R15: 2992432.2 | S15: 19.328224 | T15: 8612141.6 | U15: 27.665607 | W15: Total Biomiral | X15: 2188424.7 | Y15: 18.228729 | Z15: 10800284 | AA15: 25.03846
A18: Total Ventas de producto grav a tasa gral | B18: 16930425 | C18: 108.20081 | D18: 15998744 | E18: 103.33645 | F18: 13102800 | G18: 109.14124 | H18: 45948201 | I18: 106.52241 | K18: Total Ventas de producto grav a tasa gral | L18: 16930425 | M18: 108.20081 | N18: 16930425 | O18: 108.20081 | Q18: Total Ventas de producto grav a tasa gral | R18: 15998744 | S18: 103.33645 | T18: 32929170 | U18: 105.78153 | W18: Total Ventas de producto grav a tasa gral | X18: 13102800 | Y18: 109.14124 | Z18: 45948201 | AA18: 106.52241
A20: Dev, desctos o bonifi s vtas y/o serv tasa gral | K20: Dev, desctos o bonifi s vtas y/o serv tasa gral | Q20: Dev, desctos o bonifi s vtas y/o serv tasa gral | W20: Dev, desctos o bonifi s vtas y/o serv tasa gral
A21: Devoluciones s/venta | B21: 672752.42 | C21: 4.2994997 | D21: 130501.52 | E21: 0.84291388 | F21: 70436.43 | G21: 0.58670814 | H21: 873690.37 | I21: 2.0254895 | K21: Devoluciones s/venta | L21: 672752.42 | M21: 4.2994997 | N21: 672752.42 | O21: 4.2994997 | Q21: Devoluciones s/venta | R21: 130501.52 | S21: 0.84291388 | T21: 803253.94 | U21: 2.5803695 | W21: Devoluciones s/venta | X21: 70436.43 | Y21: 0.58670814 | Z21: 873690.37 | AA21: 2.0254895
A22: Descuento por MKT | B22: 225525.48 | C22: 1.4413129 | D22: 127931.18 | E22: 0.82631196 | F22: 528110.88 | G22: 4.3989588 | H22: 881567.54 | I22: 2.0437513 | K22: Descuento por MKT | L22: 225525.48 | M22: 1.4413129 | N22: 225525.48 | O22: 1.4413129 | Q22: Descuento por MKT | R22: 127931.18 | S22: 0.82631196 | T22: 353456.66 | U22: 1.1354427 | W22: Descuento por MKT | X22: 528110.88 | Y22: 4.3989588 | Z22: 881567.54 | AA22: 2.0437513
A23: Descuento relacion comercial | B23: 142524.59 | C23: 0.91086172 | D23: 83969.78 | E23: 0.54236374 | F23: -2757.34 | G23: -0.022967573 | H23: 139968.21 | I23: 0.32449041 | K23: Descuento relacion comercial | L23: 142524.59 | M23: 0.91086172 | N23: 142524.59 | O23: 0.91086172 | Q23: Descuento relacion comercial | R23: 83969.78 | S23: 0.54236374 | T23: 226494.37 | U23: 0.72758955 | W23: Descuento relacion comercial | X23: -2757.34 | Y23: -0.022967573 | Z23: 139968.21 | AA23: 0.32449041
A24: Descuento por piezas faltantes | B24: 24524 | C24: 0.15673066 | D24: 56.08 | E24: 0.00036222268 | F24: 1691.53 | G24: 0.014089789 | H24: 26271.61 | I24: 0.060905869 | K24: Descuento por piezas faltantes | L24: 24524 | M24: 0.15673066 | N24: 24524 | O24: 0.15673066 | Q24: Descuento por piezas faltantes | R24: 56.08 | S24: 0.00036222268 | T24: 24580.08 | U24: 0.078960945 | W24: Descuento por piezas faltantes | X24: 1691.53 | Y24: 0.014089789 | Z24: 26271.61 | AA24: 0.060905869
A25: Descuento por piezas dañadas | B25: 236.38 | C25: 0.0015106831 | D25: 1169.71 | E25: 0.0075551978 | F25: 257169.66 | G25: 2.1421235 | H25: 258575.75 | I25: 0.59946005 | K25: Descuento por piezas dañadas | L25: 236.38 | M25: 0.0015106831 | N25: 236.38 | O25: 0.0015106831 | Q25: Descuento por piezas dañadas | R25: 1169.71 | S25: 0.0075551978 | T25: 1406.09 | U25: 0.0045169175 | W25: Descuento por piezas dañadas | X25: 257169.66 | Y25: 2.1421235 | Z25: 258575.75 | AA25: 0.59946005
A26: Descuento por pronto pago (cumplimiento tyc) | B26: 215833.58 | C26: 1.3793728 | D26: 131373.67 | E26: 0.84854712 | F26: 216430.88 | G26: 1.8027853 | H26: 563638.13 | I26: 1.3066908 | K26: Descuento por pronto pago (cumplimiento tyc) | L26: 215833.58 | M26: 1.3793728 | N26: 215833.58 | O26: 1.3793728 | Q26: Descuento por pronto pago (cumplimiento tyc) | R26: 131373.67 | S26: 0.84854712 | T26: 347207.25 | U26: 1.1153671 | W26: Descuento por pronto pago (cumplimiento tyc) | X26: 216430.88 | Y26: 1.8027853 | Z26: 563638.13 | AA26: 1.3066908
A27: Descuento por error en precio | B27: 198.28 | C27: 0.0012671895 | D27: 3990.92 | E27: 0.025777492 | F27: 9131.35 | G27: 0.076060604 | H27: 13320.55 | I27: 0.030881232 | K27: Descuento por error en precio | L27: 198.28 | M27: 0.0012671895 | N27: 198.28 | O27: 0.0012671895 | Q27: Descuento por error en precio | R27: 3990.92 | S27: 0.025777492 | T27: 4189.2 | U27: 0.013457368 | W27: Descuento por error en precio | X27: 9131.35 | Y27: 0.076060604 | Z27: 13320.55 | AA27: 0.030881232
A28: Descuentos diversos | B28: 74404.91 | C28: 0.47551503 | D28: 35521.1 | E28: 0.22943203 | F28: 17226 | G28: 0.1434859 | H28: 127152.01 | I28: 0.29477842 | K28: Descuentos diversos | L28: 74404.91 | M28: 0.47551503 | N28: 74404.91 | O28: 0.47551503 | Q28: Descuentos diversos | R28: 35521.1 | S28: 0.22943203 | T28: 109926.01 | U28: 0.35312585 | W28: Descuentos diversos | X28: 17226 | Y28: 0.1434859 | Z28: 127152.01 | AA28: 0.29477842
A29: Descuento por caducidad del producto | B29: 0 | C29: 0 | D29: 9951.22 | E29: 0.064275278 | F29: 0 | G29: 0 | H29: 9951.22 | I29: 0.023070063 | K29: Descuento por caducidad del producto | L29: 0 | M29: 0 | N29: 0 | O29: 0 | Q29: Descuento por caducidad del producto | R29: 9951.22 | S29: 0.064275278 | T29: 9951.22 | U29: 0.031967257 | W29: Descuento por caducidad del producto | X29: 0 | Y29: 0 | Z29: 9951.22 | AA29: 0.023070063
A31: Total Dev | B31: -1355999.6 | C31: -8.6660707 | D31: -524465.18 | E31: -3.3875389 | F31: -1097439.4 | G31: -9.1412445 | H31: -2894135.4 | I31: -6.7095177 | K31: Total Dev | L31: -1355999.6 | M31: -8.6660707 | N31: -1355999.6 | O31: -8.6660707 | Q31: Total Dev | R31: -524465.18 | S31: -3.3875389 | T31: -1880464.8 | U31: -6.0407972 | W31: Total Dev | X31: -1097439.4 | Y31: -9.1412445 | Z31: -2894135.4 | AA31: -6.7095177
A33: Otros Ingresos | B33: =B31-B35 -> -1428799.6 | K33: Otros Ingresos | Q33: Otros Ingresos | W33: Otros Ingresos
A34: Descuento por relacion comercial | B34: 0 | C34: 0 | D34: 0 | E34: 0 | F34: 0 | G34: 0 | H34: 0 | I34: 0 | K34: Descuento por relacion comercial | L34: 0 | M34: 0 | N34: 0 | O34: 0 | Q34: Descuento por relacion comercial | R34: 0 | S34: 0 | T34: 0 | U34: 0 | W34: Descuento por relacion comercial | X34: 0 | Y34: 0 | Z34: 0 | AA34: 0
A35: Factura para afectar Nota de credito | B35: 72800 | C35: 0.46525819 | D35: 0 | E35: 0 | F35: 0 | G35: 0 | H35: 72800 | I35: 0.16877334 | K35: Factura para afectar Nota de credito | L35: 72800 | M35: 0.46525819 | N35: 72800 | O35: 0.46525819 | Q35: Factura para afectar Nota de credito | R35: 0 | S35: 0 | T35: 72800 | U35: 0.23386241 | W35: Factura para afectar Nota de credito | X35: 0 | Y35: 0 | Z35: 72800 | AA35: 0.16877334
A37: Total Otros Ingresos | B37: 72800 | C37: 0.46525819 | D37: 0 | E37: 0 | F37: 0 | G37: 0 | H37: 72800 | I37: 0.16877334 | K37: Total Otros Ingresos | L37: 72800 | M37: 0.46525819 | N37: 72800 | O37: 0.46525819 | Q37: Total Otros Ingresos | R37: 0 | S37: 0 | T37: 72800 | U37: 0.23386241 | W37: Total Otros Ingresos | X37: 0 | Y37: 0 | Z37: 72800 | AA37: 0.16877334
A40: Total Ingresos | B40: 15647226 | C40: 100 | D40: 15482189 | E40: 100 | F40: 12005361 | G40: 100 | H40: 43134776 | I40: 100 | K40: Total Ingresos | L40: 15647226 | M40: 100 | N40: 15647226 | O40: 100 | Q40: Total Ingresos | R40: 15482189 | S40: 100 | T40: 31129415 | U40: 100 | W40: Total Ingresos | X40: 12005361 | Y40: 100 | Z40: 43134776 | AA40: 100
B41: =B18+B33 -> 15501626 | D41: =D18+D31+D35 -> 15474279 | F41: =F18+F31+F35 -> 12005361 | H41: =H18+H31+H35 -> 43126866
A42: E g r e s o s | K42: E g r e s o s | Q42: E g r e s o s | W42: E g r e s o s
A44: Costos Directos | K44: Costos Directos | Q44: Costos Directos | W44: Costos Directos
A45: Materia Prima | B45: 6374777.3 | C45: 40.740623 | D45: 6554330.4 | E45: 42.334649 | F45: 4958570.6 | G45: 41.30297 | H45: 17887678 | I45: 41.469274 | K45: Materia Prima | L45: 6374777.3 | M45: 40.740623 | N45: 6374777.3 | O45: 40.740623 | Q45: Materia Prima | R45: 6554330.4 | S45: 42.334649 | T45: 12929108 | U45: 41.533411 | W45: Materia Prima | X45: 4958570.6 | Y45: 41.30297 | Z45: 17887678 | AA45: 41.469274
A46: Material Empaque | B46: 0 | C46: 0 | D46: 0 | E46: 0 | F46: 0 | G46: 0 | H46: 0 | I46: 0 | K46: Material Empaque | L46: 0 | M46: 0 | N46: 0 | O46: 0 | Q46: Material Empaque | R46: 0 | S46: 0 | T46: 0 | U46: 0 | W46: Material Empaque | X46: 0 | Y46: 0 | Z46: 0 | AA46: 0
A47: Fletes y logistica | B47: 21135.54 | C47: 0.13507532 | D47: 41265.29 | E47: 0.26653395 | F47: 111265.6 | G47: 0.9267993 | H47: 173666.43 | I47: 0.4026135 | K47: Fletes y logistica | L47: 21135.54 | M47: 0.13507532 | N47: 21135.54 | O47: 0.13507532 | Q47: Fletes y logistica | R47: 41265.29 | S47: 0.26653395 | T47: 62400.83 | U47: 0.20045616 | W47: Fletes y logistica | X47: 111265.6 | Y47: 0.9267993 | Z47: 173666.43 | AA47: 0.4026135
A48: Maniobras | B48: 136080 | C48: 0.86967493 | D48: 0 | E48: 0 | F48: 0 | G48: 0 | H48: 136080 | I48: 0.31547631 | K48: Maniobras | L48: 136080 | M48: 0.86967493 | N48: 136080 | O48: 0.86967493 | Q48: Maniobras | R48: 0 | S48: 0 | T48: 136080 | U48: 0.43714281 | W48: Maniobras | X48: 0 | Y48: 0 | Z48: 136080 | AA48: 0.31547631
A49: Mano de obra directa | B49: 2785345.6 | C49: 17.800891 | D49: 1656923.7 | E49: 10.702128 | F49: 1531318.2 | G49: 12.755287 | H49: 5973587.6 | I49: 13.848658 | K49: Mano de obra directa | L49: 2785345.6 | M49: 17.800891 | N49: 2785345.6 | O49: 17.800891 | Q49: Mano de obra directa | R49: 1656923.7 | S49: 10.702128 | T49: 4442269.4 | U49: 14.270327 | W49: Mano de obra directa | X49: 1531318.2 | Y49: 12.755287 | Z49: 5973587.6 | AA49: 13.848658
A50: Seguridad social Produccion | B50: 321486.85 | C50: 2.0545933 | D50: 648536.46 | E50: 4.1889197 | F50: 151553.91 | G50: 1.2623853 | H50: 1121577.2 | I50: 2.6001694 | K50: Seguridad social Produccion | L50: 321486.85 | M50: 2.0545933 | N50: 321486.85 | O50: 2.0545933 | Q50: Seguridad social Produccion | R50: 648536.46 | S50: 4.1889197 | T50: 970023.31 | U50: 3.1160988 | W50: Seguridad social Produccion | X50: 151553.91 | Y50: 1.2623853 | Z50: 1121577.2 | AA50: 2.6001694
A51: Gastos Generales de Produccion | B51: 126383.45 | C51: 0.80770516 | D51: 94135 | E51: 0.60802125 | F51: 105836.74 | G51: 0.881579 | H51: 326355.19 | I51: 0.75659415 | K51: Gastos Generales de Produccion | L51: 126383.45 | M51: 0.80770516 | N51: 126383.45 | O51: 0.80770516 | Q51: Gastos Generales de Produccion | R51: 94135 | S51: 0.60802125 | T51: 220518.45 | U51: 0.70839253 | W51: Gastos Generales de Produccion | X51: 105836.74 | Y51: 0.881579 | Z51: 326355.19 | AA51: 0.75659415
A52: Otros conceptos de costo | B52: 0 | C52: 0 | D52: 0 | E52: 0 | F52: 28585.2 | G52: 0.23810363 | H52: 28585.2 | I52: 0.0662695 | K52: Otros conceptos de costo | L52: 0 | M52: 0 | N52: 0 | O52: 0 | Q52: Otros conceptos de costo | R52: 0 | S52: 0 | T52: 0 | U52: 0 | W52: Otros conceptos de costo | X52: 28585.2 | Y52: 0.23810363 | Z52: 28585.2 | AA52: 0.0662695
B53: =SUM(B46:B52) -> 3390431.5 | C53: =SUM(C46:C52) -> 21.66794 | D53: =SUM(D46:D52) -> 2440860.5 | E53: =SUM(E46:E52) -> 15.765603 | F53: =SUM(F46:F52) -> 1928559.7 | G53: =SUM(G46:G52) -> 16.064154 | H53: =SUM(H46:H52) -> 7759851.6 | I53: =SUM(I46:I52) -> 17.989781
...

Sheet Linea Sesajal
C2: Monto | D2: 65000000
C3: Tasa | D3: 0.135
C4: Use of Funds
C5: WC | D5: =D2*0.3 -> 19500000
C6: Debt | D6: =D2*0.7 -> 45500000
D10: 6 | E10: 7 | F10: 8 | G10: 9 | H10: 10 | I10: 11 | J10: 12 | K10: 2025 | L10: 1 | M10: 2 | N10: 3 | O10: 4 | P10: 5 | Q10: 6 | R10: 7 | S10: 8 | T10: 9 | U10: 10 | V10: 11 | W10: 12 | X10: 2026 | Y10: 1 | Z10: 2 | AA10: 3 | AB10: 4 | AC10: 5 | AD10: 6 | AE10: 7 | AF10: 8 | AG10: 9 | AH10: 10 | AI10: 11 | AJ10: 12 | AK10: 2027
B11: Capital X | C11: Capital X BOP | D11: ='[1]Interest Ex Comp'!C6 -> 26325913
B12: Capital X | C12: Vencimientos v Capital X | D12: =3621046.2-2000000+564540.69-265771.23 -> 1919815.7 | E12: =9279261.66+2223775.68 -> 11503037 | F12: =8584220.4+2111385.96 -> 10695606 | G12: =1040155.47+832701.4 -> 1872856.9
B13: Capital X | C13: Facturación KPS | D13: =8869900-400000 -> 8469900 | E13: =10937625+3000000 -> 13937625 | F13: =7452000+3000000 -> 10452000 | G13: =5490600+3000000 -> 8490600 | H13: 3615100 | I13: 6540100 | J13: 4591100
B14: Capital X | C14: Nuevos Vencimientos KPS | G14: =(D13+E13)/2 -> 11203762 | H14: =(E13+F13)/2 -> 12194812 | I14: =(F13+G13)/2 -> 9471300 | J14: =(G13+H13)/2 -> 6052850
C16: FLUJO DE OPERACIONES
C17: Flujo Neto de Operación Modelo | D17: ='Cashflow (ROLLING) CAP'!G25 -> -1272887.1 | E17: ='Cashflow (ROLLING) CAP'!H25 -> -58721.611 | F17: ='Cashflow (ROLLING) CAP'!I25 -> 3028285.7 | G17: ='Cashflow (ROLLING) CAP'!J25 -> 1986246.5 | H17: ='Cashflow (ROLLING) CAP'!K25 -> 4019526.4 | I17: ='Cashflow (ROLLING) CAP'!L25 -> 5088108.9 | J17: ='Cashflow (ROLLING) CAP'!M25 -> 3904674.8 | K17: =SUM(D17:J17) -> 16695234 | L17: ='Cashflow (ROLLING) CAP'!O25 -> 3109617.5 | M17: ='Cashflow (ROLLING) CAP'!P25 -> 2190048.2 | N17: ='Cashflow (ROLLING) CAP'!L25 -> 5088108.9 | O17: ='Cashflow (ROLLING) CAP'!R25 -> 4468012.1 | P17: ='Cashflow (ROLLING) CAP'!S25 -> 2174583.7 | Q17: ='Cashflow (ROLLING) CAP'!T25 -> -241120.19 | R17: ='Cashflow (ROLLING) CAP'!U25 -> 3306471.5 | S17: ='Cashflow (ROLLING) CAP'!V25 -> 4979840.6 | T17: ='Cashflow (ROLLING) CAP'!W25 -> 2864018.7 | U17: ='Cashflow (ROLLING) CAP'!X25 -> 6295349.5 | V17: ='Cashflow (ROLLING) CAP'!Y25 -> 7627057.6 | W17: ='Cashflow (ROLLING) CAP'!Z25 -> 6268728.4 | X17: =SUM(L17:W17) -> 48130716 | Y17: ='Cashflow (ROLLING) CAP'!AB25 -> 5389307.7 | Z17: ='Cashflow (ROLLING) CAP'!AC25 -> 4243541 | AA17: ='Cashflow (ROLLING) CAP'!AD25 -> 6253589.1 | AB17: ='Cashflow (ROLLING) CAP'!AE25 -> 7205504.2 | AC17: ='Cashflow (ROLLING) CAP'!AF25 -> 4311318.2 | AD17: ='Cashflow (ROLLING) CAP'!AG25 -> 1247348.4 | AE17: ='Cashflow (ROLLING) CAP'!AH25 -> 5229713.4 | AF17: ='Cashflow (ROLLING) CAP'!AI25 -> 7465391.7 | ... AJ17: ='Cashflow (ROLLING) CAP'!AM25 -> 8948999.5 | AK17: =SUM(Y17:AJ17) -> 74689577
B18: WC | C18: Crecimiento v Modelo | E18: 7308875.2 | F18: 6103093 | G18: 1517615.4 | H18: 0 | I18: 0 | J18: 0
B19: WC | C19: Req Adicional Modelo WC H2 | E19: =(D18*0.4)*(100/30) -> 0 | F19: =(E18*0.4) -> 2923550.1 | G19: =(F18*0.4) -> 2441237.2 | H19: =(G18*0.4) -> 607046.16 | I19: =(H18*0.4)*(100/30) -> 0 | J19: =(J18*0.4)*(100/30) -> 0 | K19: =SUM(D19:J19) -> 5971833.4
C20: Flujo Neto de Operaciones | D20: =D17-D19 -> -1272887.1 | E20: =E17-E19 -> -58721.611 | F20: =F17-F19 -> 104735.58 | G20: =G17-G19 -> -454990.68 | H20: =H17-H19 -> 3412480.3 | I20: =I17-I19 -> 5088108.9 | J20: =J17-J19 -> 3904674.8 | K20: =SUM(D20:J20) -> 10723400 | L20: =L17-L19 -> 3109617.5 | M20: =M17-M19 -> 2190048.2 | N20: =N17-N19 -> 5088108.9 | O20: =O17-O19 -> 4468012.1 | P20: =P17-P19 -> 2174583.7 | Q20: =Q17-Q19 -> -241120.19 | R20: =R17-R19 -> 3306471.5 | S20: =S17-S19 -> 4979840.6 | ... W20: =W17-W19 -> 6268728.4 | Y20: =Y17-Y19 -> 5389307.7 | Z20: =Z17-Z19 -> 4243541 | AA20: =AA17-AA19 -> 6253589.1 | AB20: =AB17-AB19 -> 7205504.2 | AC20: =AC17-AC19 -> 4311318.2 | AD20: =AD17-AD19 -> 1247348.4 | AE20: =AE17-AE19 -> 5229713.4 | AF20: =AF17-AF19 -> 7465391.7 | ... AJ20: =AJ17-AJ19 -> 8948999.5
C22: Escenarios Intereses
C23: Reestructura Sesajal | D23: 1200000 | E23: ='Interest Expense'!R31 -> 860955.61 | F23: ='Interest Expense'!S31 -> 1267197.2 | G23: ='Interest Expense'!T31 -> 1435839.3 | H23: ='Interest Expense'!U31 -> 1503784.3 | I23: ='Interest Expense'!V31 -> 1497283.3 | J23: ='Interest Expense'!W31 -> 1490677.2 | K23: =SUM(D23:J23) -> 9255736.9 | L23: ='Interest Expense'!Y31 -> 1483963.4 | M23: ='Interest Expense'!Z31 -> 1477139.7 | N23: ='Interest Expense'!AA31 -> 1456401.4 | O23: ='Interest Expense'!AB31 -> 1430517.1 | P23: ='Interest Expense'!AC31 -> 1409802 | Q23: ='Interest Expense'!AD31 -> 1385909.2 | R23: ='Interest Expense'!AE31 -> 1365318.4 | S23: ='Interest Expense'!AF31 -> 1341888.3 | ... W23: ='Interest Expense'!AJ31 -> 1258523.4 | X23: =SUM(L23:W23) -> 16508198 | Y23: ='Interest Expense'!AL31 -> 725835.34 | Z23: ='Interest Expense'!AM31 -> 705709.12 | AA23: ='Interest Expense'!AN31 -> 685472.38 | AB23: ='Interest Expense'!AO31 -> 665122.74 | AC23: ='Interest Expense'!AP31 -> 644657.74 | AD23: ='Interest Expense'!AQ31 -> 624074.88 | AE23: ='Interest Expense'!AR31 -> 603371.62 | AF23: ='Interest Expense'!AS31 -> 582545.34 | ... AJ23: ='Interest Expense'!AW31 -> 501626.27 | AK23: =SUM(Y23:AJ23) -> 7363493.7
C24: Reestructura Nuvari | D24: ='Interest Expense'!Q43 -> 1188520.6 | E24: ='Interest Expense'!R43 -> 1712746.7 | F24: ='Interest Expense'!S43 -> 1886689.5 | G24: ='Interest Expense'!T43 -> 1964133.3 | H24: ='Interest Expense'!U43 -> 2029898.3 | I24: ='Interest Expense'!V43 -> 2004383.5 | J24: ='Interest Expense'!W43 -> 2010277.3 | K24: =SUM(D24:J24) -> 12796649 | L24: ='Interest Expense'!Y43 -> 2003563.5 | M24: ='Interest Expense'!Z43 -> 1996739.8 | N24: ='Interest Expense'!AA43 -> 1989803.6 | O24: ='Interest Expense'!AB43 -> 1977721.4 | P24: ='Interest Expense'!AC43 -> 1970808.4 | Q24: ='Interest Expense'!AD43 -> 1960717.7 | R24: ='Interest Expense'!AE43 -> 1953929 | S24: ='Interest Expense'!AF43 -> 1944300.9 | ... W24: ='Interest Expense'!AJ43 -> 1916144.4 | X24: =SUM(L24:W24) -> 23502514 | Y24: ='Interest Expense'!AL43 -> 1076611.1 | Z24: ='Interest Expense'!AM43 -> 1070287 | AA24: ='Interest Expense'!AN43 -> 1063852.3 | AB24: ='Interest Expense'!AO43 -> 1057304.8 | AC24: ='Interest Expense'!AP43 -> 1050641.9 | AD24: ='Interest Expense'!AQ43 -> 1043861.1 | AE24: ='Interest Expense'!AR43 -> 1036959.9 | AF24: ='Interest Expense'!AS43 -> 0 | ... AJ24: ='Interest Expense'!AW43 -> 0
C27: Flujo Neto con Sesajal | D27: =D20-D23 -> -2472887.1 | E27: =E20-E23 -> -919677.22 | F27: =F20-F23 -> -1162461.6 | G27: =G20-G23 -> -1890830 | H27: =H20-H23 -> 1908696 | I27: =I20-I23 -> 3590825.6 | J27: =J20-J23 -> 2413997.6 | K27: =SUM(D27:J27) -> 1467663.2 | L27: =L20-L23 -> 1625654.1 | M27: =M20-M23 -> 712908.5 | N27: =N20-N23 -> 3631707.5 | O27: =O20-O23 -> 3037495 | P27: =P20-P23 -> 764781.71 | Q27: =Q20-Q23 -> -1627029.4 | R27: =R20-R23 -> 1941153 | S27: =S20-S23 -> 3637952.3 | ... W27: =W20-W23 -> 5010205 | X27: =SUM(L27:W27) -> 31622518 | Y27: =Y20-Y23 -> 4663472.3 | Z27: =Z20-Z23 -> 3537831.9 | AA27: =AA20-AA23 -> 5568116.7 | AB27: =AB20-AB23 -> 6540381.5 | AC27: =AC20-AC23 -> 3666660.4 | AD27: =AD20-AD23 -> 623273.56 | AE27: =AE20-AE23 -> 4626341.8 | AF27: =AF20-AF23 -> 6882846.3 | ... AJ27: =AJ20-AJ23 -> 8447373.3 | AK27: =SUM(Y27:AJ27) -> 67326083
C28: Flujo Acumulado c/ Sesajal | D28: =D27 -> -2472887.1 | E28: =E27+D28 -> -3392564.3 | F28: =F27+E28 -> -4555026 | G28: =G27+F28 -> -6445855.9 | H28: =H27+G28 -> -4537160 | I28: =I27+H28 -> -946334.4 | J28: =J27+I28 -> 1467663.2 | K28: =J28 -> 1467663.2 | L28: =L27+K28 -> 3093317.3 | M28: =M27+L28 -> 3806225.8 | N28: =N27+M28 -> 7437933.3 | O28: =O27+N28 -> 10475428 | P28: =P27+O28 -> 11240210 | Q28: =Q27+P28 -> 9613180.7 | R28: =R27+Q28 -> 11554334 | S28: =S27+R28 -> 15192286 | ... W28: =W27+V28 -> 33090181 | X28: =W28 -> 33090181 | Y28: =Y27+X28 -> 37753654 | Z28: =Z27+Y28 -> 41291486 | AA28: =AA27+Z28 -> 46859602 | AB28: =AB27+AA28 -> 53399984 | AC28: =AC27+AB28 -> 57066644 | AD28: =AD27+AC28 -> 57689918 | AE28: =AE27+AD28 -> 62316260 | AF28: =AF27+AE28 -> 69199106 | ... AJ28: =AJ27+AI28 -> 1.0041626e+08 | AK28: =AJ28 -> 1.0041626e+08
C30: Flujo Neto con Nuvari | D30: =D20-D24 -> -2461407.7 | E30: =E20-E24 -> -1771468.3 | F30: =F20-F24 -> -1781953.9 | G30: =G20-G24 -> -2419124 | H30: =H20-H24 -> 1382582 | I30: =I20-I24 -> 3083725.4 | J30: =J20-J24 -> 1894397.5 | K30: =SUM(D30:J30) -> -2073249 | L30: =L20-L24 -> 1106053.9 | M30: =M20-M24 -> 193308.37 | N30: =N20-N24 -> 3098305.3 | O30: =O20-O24 -> 2490290.7 | P30: =P20-P24 -> 203775.33 | Q30: =Q20-Q24 -> -2201837.8 | R30: =R20-R24 -> 1352542.5 | S30: =S20-S24 -> 3035539.6 | ... W30: =W20-W24 -> 4352584 | X30: =SUM(L30:W30) -> 24628202 | Y30: =Y20-Y24 -> 4312696.5 | Z30: =Z20-Z24 -> 3173254 | AA30: =AA20-AA24 -> 5189736.7 | AB30: =AB20-AB24 -> 6148199.4 | AC30: =AC20-AC24 -> 3260676.3 | AD30: =AD20-AD24 -> 203487.35 | AE30: =AE20-AE24 -> 4192753.5 | AF30: =AF20-AF24 -> 7465391.7 | ... AJ30: =AJ20-AJ24 -> 8948999.5 | AK30: =SUM(Y30:AJ30) -> 67290059
C31: Flujo Acumulado c/ Nuvari | D31: =D30 -> -2461407.7 | E31: =E30+D31 -> -4232876 | F31: =F30+E31 -> -6014829.9 | G31: =G30+F31 -> -8433953.9 | H31: =H30+G31 -> -7051371.9 | I31: =I30+H31 -> -3967646.4 | J31: =J30+I31 -> -2073249 | K31: =J31 -> -2073249 | L31: =L30+K31 -> -967195.02 | M31: =M30+L31 -> -773886.65 | N31: =N30+M31 -> 2324418.7 | O31: =O30+N31 -> 4814709.4 | P31: =P30+O31 -> 5018484.7 | Q31: =Q30+P31 -> 2816646.9 | R31: =R30+Q31 -> 4169189.4 | S31: =S30+R31 -> 7204729 | ... W31: =W30+V31 -> 22554953 | X31: =W31 -> 22554953 | Y31: =Y30+X31 -> 26867650 | Z31: =Z30+Y31 -> 30040904 | AA31: =AA30+Z31 -> 35230640 | AB31: =AB30+AA31 -> 41378840 | AC31: =AC30+AB31 -> 44639516 | AD31: =AD30+AC31 -> 44843003 | AE31: =AE30+AD31 -> 49035757 | AF31: =AF30+AE31 -> 56501149 | ... AJ31: =AJ30+AI31 -> 89845012 | AK31: =AJ31 -> 89845012
C36: Use of Funds
C37: WC | D37: =IF(D27<0,-D27,0) -> 2472887.1 | E37: =IF(E27<0,-E27,0) -> 919677.22 | F37: =IF(F27<0,-F27,0) -> 1162461.6 | G37: =IF(G27<0,-G27,0) -> 1890830 | H37: =IF(H27<0,-H27,0) -> 0 | I37: =IF(I27<0,-I27,0) -> 0 | J37: =IF(J27<0,-J27,0) -> 0 | K37: =SUM(D37:J37) -> 6445855.9 | X37: =SUM(L37:W37) -> 0 | AK37: =SUM(Y37:AJ37) -> 0
C38: CAPEX | E38: 750000 | F38: 750000 | G38: 750000 | H38: 750000 | I38: 750000 | J38: 750000 | K38: =SUM(D38:J38) -> 4500000 | L38: 750000 | M38: 750000 | N38: 750000 | O38: 750000 | P38: 750000 | Q38: 750000 | R38: 750000 | S38: 750000 | T38: 750000 | U38: 750000 | V38: 750000 | W38: 750000 | X38: =SUM(L38:W38) -> 9000000 | AK38: =SUM(Y38:AJ38) -> 0
C39: Total para WC/CAPEX | D39: =SUM(D37:D38) -> 2472887.1 | E39: =SUM(E37:E38) -> 1669677.2 | F39: =SUM(F37:F38) -> 1912461.6 | G39: =SUM(G37:G38) -> 2640830 | H39: =SUM(H37:H38) -> 750000 | I39: =SUM(I37:I38) -> 750000 | J39: =SUM(J37:J38) -> 750000 | K39: =SUM(D39:J39) -> 10945856 | X39: =SUM(L39:W39) -> 0 | AK39: =SUM(Y39:AJ39) -> 0
C40: Uso para WC Acumulado | D40: =D39 -> 2472887.1 | E40: =E39+D40 -> 4142564.3 | F40: =F39+E40 -> 6055026 | G40: =G39+F40 -> 8695855.9 | H40: =H39+G40 -> 9445855.9 | I40: =I39+H40 -> 10195856 | J40: =J39+I40 -> 10945856 | K40: =J40 -> 10945856 | X40: =W40 -> 0 | AK40: =AJ40 -> 0
C41: Uso para WC (%) | D41: =D40/$D$5 -> 0.12681472 | E41: =E40/$D$5 -> 0.2124392 | F41: =F40/$D$5 -> 0.31051415 | G41: =G40/$D$5 -> 0.44594133 | H41: =H40/$D$5 -> 0.48440287 | I41: =I40/$D$5 -> 0.52286441 | J41: =J40/$D$5 -> 0.56132594 | K41: =J41 -> 0.56132594 | X41: =W41 -> 0 | AK41: =AJ41 -> 0
C43: Capital X | D43: =D12 -> 1919815.7 | E43: =E12 -> 11503037 | F43: =F12 -> 10695606 | G43: =G12 -> 1872856.9 | H43: =H12 -> 0 | I43: =I12 -> 0 | J43: =J12 -> 0 | K43: =SUM(D43:J43) -> 25991316 | L43: 100% Uso de la linea | X43: =SUM(L43:W43) -> 0 | AK43: =SUM(Y43:AJ43) -> 0
C44: Arrendamas | K44: =SUM(D44:J44) -> 0 | X44: =SUM(L44:W44) -> 0 | AK44: =SUM(Y44:AJ44) -> 0
C45: Nuvari | E45: 13500000 | K45: =SUM(D45:J45) -> 13500000 | X45: =SUM(L45:W45) -> 0 | AK45: =SUM(Y45:AJ45) -> 0
C46: Capix | E46: 0 | G46: 1000000 | H46: 1000000 | K46: =SUM(D46:J46) -> 2000000 | X46: =SUM(L46:W46) -> 0 | AK46: =SUM(Y46:AJ46) -> 0
C47: Total para Deuda | D47: =SUM(D43:D46) -> 1919815.7 | E47: =SUM(E43:E46) -> 25003037 | F47: =SUM(F43:F46) -> 10695606 | G47: =SUM(G43:G46) -> 2872856.9 | H47: =SUM(H43:H46) -> 1000000 | K47: =SUM(D47:J47) -> 41491316 | X47: =SUM(L47:W47) -> 0 | AK47: =SUM(Y47:AJ47) -> 0
C48: Uso para Deuda Acumulado | D48: =D47 -> 1919815.7 | E48: =E47+D48 -> 26922853 | F48: =F47+E48 -> 37618459 | G48: =G47+F48 -> 40491316 | H48: =H47+G48 -> 41491316 | I48: =I47+H48 -> 41491316 | J48: =J47+I48 -> 41491316 | K48: =J48 -> 41491316 | X48: =W48 -> 0 | AK48: =AJ48 -> 0
C49: Uso para Deuda (%) | D49: =D48/$D$6 -> 0.042193751 | E49: =E48/$D$6 -> 0.59171105 | F49: =F48/$D$6 -> 0.82677933 | G49: =G48/$D$6 -> 0.88991904 | H49: =H48/$D$6 -> 0.91189706 | I49: =I48/$D$6 -> 0.91189706 | J49: =J48/$D$6 -> 0.91189706 | K49: =J49 -> 0.91189706 | X49: =W49 -> 0 | AK49: =AJ49 -> 0
C51: Disposición Total por periodo | E51: 36000000 | F51: 12794983 | G51: 5000000 | H51: =H47+H39 -> 1750000 | I51: =I47+I39 -> 750000 | J51: =J47+J39 -> 750000 | K51: =SUM(D51:J51) -> 57044983 | X51: =SUM(L51:W51) -> 0 | AK51: =SUM(Y51:AJ51) -> 0
C52: Uso Total Acumulado | D52: =SUM($D51:D51) -> 0 | E52: =SUM($D51:E51) -> 36000000 | F52: =SUM($D51:F51) -> 48794983 | G52: =SUM($D51:G51) -> 53794983 | H52: =SUM($D51:H51) -> 55544983 | I52: =SUM($D51:I51) -> 56294983 | J52: =SUM($D51:J51) -> 57044983 | K52: =J52 -> 57044983 | X52: =W52 -> 0 | AK52: =AJ52 -> 0
C53: Uso Total (%) | D53: =D52/$D$2 -> 0 | E53: =E52/$D$2 -> 0.55384615 | F53: =F52/$D$2 -> 0.75069205 | G53: =G52/$D$2 -> 0.82761513 | H53: =H52/$D$2 -> 0.85453821 | I53: =I52/$D$2 -> 0.86607667 | J53: =J52/$D$2 -> 0.87761513 | K53: =J53 -> 0.87761513 | X53: =W53 -> 0 | AK53: =AJ53 -> 0
C55: Interest Expense | D55: 28732.668 | E55: 478766.84 | F55: 622710.4 | G55: 643780.04 | H55: 643780.04 | I55: 643780.04 | J55: 643780.04
C56: PAGO DE DEUDA
...

Sheet Cashflow (ROLLING) CAP
A1: 2025
A2: Prom | B2: ='[2]P&L CONSOLIDADO Mensual'!$C$94 -> 19.0171 | C2: ='[2]P&L CONSOLIDADO Mensual'!$F$94 -> 18.6222 | D2: ='[2]P&L CONSOLIDADO Mensual'!$I$94 -> 18.3887 | E2: ='[2]P&L CONSOLIDADO Mensual'!$L$94 -> 18.0879 | F2: ='[2]P&L CONSOLIDADO Mensual'!$O$94 -> 17.7489 | G2: ='[2]P&L CONSOLIDADO Mensual'!$R$94 -> 17.2688 | H2: ='[2]P&L CONSOLIDADO Mensual'!$U$94 -> 0 | I2: ='[2]P&L CONSOLIDADO Mensual'!$X$94 -> 0 | J2: ='[2]P&L CONSOLIDADO Mensual'!$AA$94 -> 0 | K2: ='[2]P&L CONSOLIDADO Mensual'!$AD$94 -> 0 | L2: ='[2]P&L CONSOLIDADO Mensual'!$AG$94 -> 0 | M2: ='[2]P&L CONSOLIDADO Mensual'!$AJ$94 -> 0 | N2: ='[2]P&L CONSOLIDADO Mensual'!$AN$94 -> 0 | P2: =687500 -> 687500 | Q2: 0.275 | R2: =(Q2/365)*80*S2 -> 687500 | S2: 11406250 | T2: =P2-R2 -> 0 | AA2: ='[2]P&L CONSOLIDADO Mensual'!$AN$94 -> 0 | AN2: ='[2]P&L CONSOLIDADO Mensual'!$AN$94 -> 0
A3: ='[2]P&L CONSOLIDADO Mensual'!B95 -> 19.3615 | B3: ='[2]P&L CONSOLIDADO Mensual'!$C$95 -> 18.7793 | C3: ='[2]P&L CONSOLIDADO Mensual'!$F$95 -> 18.4077 | D3: ='[2]P&L CONSOLIDADO Mensual'!$I$95 -> 18.0932 | E3: ='[2]P&L CONSOLIDADO Mensual'!$L$95 -> 18.0723 | F3: ='[2]P&L CONSOLIDADO Mensual'!$O$95 -> 17.6532 | G3: ='[2]P&L CONSOLIDADO Mensual'!$R$95 -> 17.1187 | H3: ='[2]P&L CONSOLIDADO Mensual'!$U$95 -> 17 | I3: ='[2]P&L CONSOLIDADO Mensual'!$X$95 -> 17 | J3: ='[2]P&L CONSOLIDADO Mensual'!$AA$95 -> 17 | K3: ='[2]P&L CONSOLIDADO Mensual'!$AD$95 -> 17.5 | L3: ='[2]P&L CONSOLIDADO Mensual'!$AG$95 -> 17.5 | M3: ='[2]P&L CONSOLIDADO Mensual'!$AJ$95 -> 17.5 | N3: ='[2]P&L CONSOLIDADO Mensual'!$AN$95 -> 17.635367 | AA3: ='[2]P&L CONSOLIDADO Mensual'!$AN$95 -> 17.635367 | AN3: ='[2]P&L CONSOLIDADO Mensual'!$AN$95 -> 17.635367
B4: Enero Real | C4: Febrero Real | D4: Marzo Real | E4: Abril | F4: Mayo | G4: Junio | H4: Julio | I4: Agosto | J4: Septiembre | K4: Octubre | L4: Noviembre | M4: Diciembre | N4: Total | O4: Enero | P4: Febero | Q4: Marzo | R4: Abril | S4: Mayo | T4: Junio | U4: Julio | V4: Agosto | W4: Septiembre | X4: Octubre | Y4: Noviembre | Z4: Diciembre | AA4: Total | AB4: Enero | AC4: Febero | AD4: Marzo | AE4: Abril | AF4: Mayo | AG4: Junio | AH4: Julio | AI4: Agosto | AJ4: Septiembre | AK4: Octubre | AL4: Noviembre | AM4: Diciembre | AN4: Total
A6: COBRANZA | F6: =(C158+D158)/2 -> 14260345 | G6: =(D158+E158)/2 -> 14870117 | H6: =(E158+F158)/2 -> 19009321 | I6: =(F158+G158)/2 -> 19040750 | J6: =(G158+H158)/2 -> 20273981 | K6: =(H158+I158)/2 -> 24100483 | L6: =(I158+J158)/2 -> 23696498 | M6: =(J158+K158)/2 -> 22301535 | N6: =SUM(B6,C6,D6,E6,F6,G6,H6,I6,J6,K6,L6,M6) -> 1.5755303e+08 | O6: =(K158+L158)/2 -> 21006410 | P6: =(L158+M158)/2 -> 20598558 | Q6: =(M158+O158)/2 -> 22155402 | R6: =(O158+P158)/2 -> 21548104 | S6: =(P158+Q158)/2 -> 18095932 | T6: =(Q158+R158)/2 -> 19012086 | U6: =(R158+S158)/2 -> 23924452 | V6: =(S158+T158)/2 -> 23903384 | W6: =(T158+U158)/2 -> 25450155 | X6: =(U158+V158)/2 -> 30085459 | Y6: =(V158+W158)/2 -> 29620623 | Z6: =(W158+X158)/2 -> 27876918 | AA6: =SUM(O6,P6,Q6,R6,S6,T6,U6,V6,W6,X6,Y6,Z6) -> 2.8327748e+08 | AB6: =(X158+Y158)/2 -> 26258012 | AC6: =(Y158+Z158)/2 -> 25748197 | AD6: =(Z158+AB158)/2 -> 27675386 | AE6: =(AB158+AC158)/2 -> 26915921 | AF6: =(AC158+AD158)/2 -> 22692721 | AG6: =(AD158+AE158)/2 -> 23589175 | AH6: =(AE158+AF158)/2 -> 29564240 | AI6: =(AF158+AG158)/2 -> 29777183 | AJ6: =(AG158+AH158)/2 -> 31540657 | AK6: =(AH158+AI158)/2 -> 37088171 | AL6: =(AI158+AJ158)/2 -> 36560233 | AM6: =(AJ158+AK158)/2 -> 34531059 | AN6: =SUM(AB6,AC6,AD6,AE6,AF6,AG6,AH6,AI6,AJ6,AK6,AL6,AM6) -> 3.5194096e+08
A7: Intercompañías | F7: =F6*$AQ7 -> 10970093 | G7: =G6*$AQ7 -> 11439174 | H7: =H6*$AQ7 -> 14623350 | I7: =I6*$AQ7 -> 14647528 | J7: =J6*$AQ7 -> 15596219 | K7: =K6*$AQ7 -> 18539842 | L7: =L6*$AQ7 -> 18229068 | M7: =M6*$AQ7 -> 17155960 | N7: =SUM(B7,C7,D7,E7,F7,G7,H7,I7,J7,K7,L7,M7) -> 1.2120123e+08 | AA7: =SUM(O7,P7,Q7,R7,S7,T7,U7,V7,W7,X7,Y7,Z7) -> 0 | AN7: =SUM(AB7,AC7,AD7,AE7,AF7,AG7,AH7,AI7,AJ7,AK7,AL7,AM7) -> 0 | AQ7: 0.76927264 | AR7: =N7/($N$7+$N$8) -> 0.81252764
A8: Terceros | F8: =F7*$AQ8 -> 2531100.7 | G8: =G7*$AQ8 -> 2639330.6 | H8: =H7*$AQ8 -> 3374007.1 | I8: =I7*$AQ8 -> 3379585.5 | J8: =J7*$AQ8 -> 3598474.5 | K8: =K7*$AQ8 -> 4277648.9 | L8: =L7*$AQ8 -> 4205944.8 | M8: =M7*$AQ8 -> 3958349.5 | N8: =SUM(B8,C8,D8,E8,F8,G8,H8,I8,J8,K8,L8,M8) -> 27964441 | AA8: =SUM(O8,P8,Q8,R8,S8,T8,U8,V8,W8,X8,Y8,Z8) -> 0 | AN8: =SUM(AB8,AC8,AD8,AE8,AF8,AG8,AH8,AI8,AJ8,AK8,AL8,AM8) -> 0 | AQ8: 0.23072736 | AR8: =N8/($N$7+$N$8) -> 0.18747236
A9: Otros Ingresos
A11: PAGOS | F11: =+F13+F16+F18 -> 15405064 | G11: =+G13+G16+G18 -> 16143005 | H11: =+H13+H16+H18 -> 19068042 | I11: =+I13+I16+I18 -> 16012464 | J11: =+J13+J16+J18 -> 18287735 | K11: =+K13+K16+K18 -> 20080957 | L11: =+L13+L16+L18 -> 18608389 | M11: =+M13+M16+M18 -> 18396860 | ... AN11: =+AN13+AN16+AN18 -> 2.7725138e+08
A13: Materia Prima | B13: =B14+B15 -> 7018327 | C13: =C14+C15 -> 6012174 | D13: =D14+D15 -> 4998331 | E13: =C159 -> 6015156.4 | F13: =D159 -> 5001313.3 | G13: =E159 -> 6747553.1 | H13: =F159 -> 9012876 | I13: =G159 -> 7262528.2 | J13: =H159 -> 10160675 | K13: =I159 -> 11742139 | L13: =J159 -> 10489663 | M13: =K159 -> 10119142 | N13: =SUM(B13,C13,D13,E13,F13,G13,H13,I13,J13,K13,L13,M13) -> 94579878 | O13: =L159 -> 9023722.2 | P13: =M159 -> 9812380.5 | Q13: =O159 -> 10128671 | R13: =P159 -> 8834817.6 | S13: =Q159 -> 6800166.5 | T13: =R159 -> 10450621 | U13: =S159 -> 11722360 | V13: =T159 -> 9736100.8 | W13: =U159 -> 13679304 | X13: =V159 -> 14677673 | ... Z13: =X159 -> 12648927 | AA13: =SUM(O13,P13,Q13,R13,S13,T13,U13,V13,W13,X13,Y13,Z13) -> 1.3062682e+08 | AB13: =Y159 -> 11279653 | AC13: =Z159 -> 12265476 | AD13: =AB159 -> 12550599 | AE13: =AC159 -> 10961010 | AF13: =AD159 -> 8498859.5 | AG13: =AE159 -> 12755107 | AH13: =AF159 -> 14470091 | AI13: =AG159 -> 12076273 | AJ13: =AH159 -> 16756796 | AK13: =AI159 -> 18002606 | ... AM13: =AK159 -> 15612480 | AN13: =SUM(AB13,AC13,AD13,AE13,AF13,AG13,AH13,AI13,AJ13,AK13,AL13,AM13) -> 1.6132779e+08 | AQ13: =SUM(B13,C13,D13,E13,F13:M13) -> 94579878 | AS13: "COSTO" en Flujo | AT13: COSTO en P&L
A14: MP Nacional | B14: =(B$141-B$16)*$AR14 -> 4765471.5 | C14: =(C$141-C$16)*$AR14 -> 4082289.7 | D14: =(D$141-D$16)*$AR14 -> 3393886.3 | E14: =(E$141-E$16)*$AR14 -> 4579589.9 | F14: =(F$141-F$16)*$AR14 -> 6117753 | G14: =(G$141-G$16)*$AR14 -> 4929260 | H14: =(H$141-H$16)*$AR14 -> 6897113.3 | I14: =(I$141-I$16)*$AR14 -> 7970933.1 | ... M14: =(M$141-M$16)*$AR14 -> 6660619.7 | N14: =SUM(B14,C14,D14,E14,F14,G14,H14,I14,J14,K14,L14,M14) -> 69511443 | AA14: =SUM(O14,P14,Q14,R14,S14,T14,U14,V14,W14,X14,Y14,Z14) -> 0 | AN14: =SUM(AB14,AC14,AD14,AE14,AF14,AG14,AH14,AI14,AJ14,AK14,AL14,AM14) -> 0 | AQ14: =SUM(B14,C14,D14,E14,F14:M14) -> 69511443 | AR14: 0.67900391 | AS14: =N13+N16 -> 94615667 | AT14: =N159 -> 1.0240846e+08
A15: MP Internacional | B15: =(B$141-B$16)*$AR15 -> 2252855.5 | C15: =(C$141-C$16)*$AR15 -> 1929884.3 | D15: =(D$141-D$16)*$AR15 -> 1604444.7 | E15: =(E$141-E$16)*$AR15 -> 2164980.8 | F15: =(F$141-F$16)*$AR15 -> 2892140.6 | G15: =(G$141-G$16)*$AR15 -> 2330285.8 | H15: =(H$141-H$16)*$AR15 -> 3260579.7 | I15: =(I$141-I$16)*$AR15 -> 3768223.3 | ... M15: =(M$141-M$16)*$AR15 -> 3148778.4 | N15: =SUM(B15,C15,D15,E15,F15,G15,H15,I15,J15,K15,L15,M15) -> 32861227 | AA15: =SUM(O15,P15,Q15,R15,S15,T15,U15,V15,W15,X15,Y15,Z15) -> 0 | AN15: =SUM(AB15,AC15,AD15,AE15,AF15,AG15,AH15,AI15,AJ15,AK15,AL15,AM15) -> 0 | AQ15: =SUM(B15,C15,D15,E15,F15:M15) -> 32861227 | AR15: 0.32099609
A16: Empaque | B16: 2982.3957 | C16: 2982.3957 | D16: 2982.3957 | E16: 2982.3957 | F16: 2982.3957 | G16: 2982.3957 | H16: 2982.3957 | I16: 2982.3957 | J16: 2982.3957 | K16: 2982.3957 | L16: 2982.3957 | M16: 2982.3957 | N16: =SUM(B16,C16,D16,E16,F16,G16,H16,I16,J16,K16,L16,M16) -> 35788.749 | AA16: =SUM(O16,P16,Q16,R16,S16,T16,U16,V16,W16,X16,Y16,Z16) -> 0 | AN16: =SUM(AB16,AC16,AD16,AE16,AF16,AG16,AH16,AI16,AJ16,AK16,AL16,AM16) -> 0 | AQ16: =SUM(B16,C16,D16,E16,F16:M16) -> 35788.749
A18: OBS | B18: =SUM(B19:B23) -> 12019046 | C18: =SUM(C19:C23) -> 10041523 | D18: =SUM(D19:D23) -> 10835222 | E18: =SUM(E19:E23) -> 9669395.3 | F18: =SUM(F19:F23) -> 10400768 | G18: =SUM(G19:G23) -> 9392469 | H18: =SUM(H19:H23) -> 10052184 | I18: =SUM(I19:I23) -> 8746953.6 | ... M18: =SUM(M19:M23) -> 8274735.7 | N18: =SUM(B18,C18,D18,E18,F18,G18,H18,I18,J18,K18,L18,M18) -> 1.1400795e+08 | O18: =SUM(O19:O23) -> 8873070.3 | P18: =SUM(P19:P23) -> 8596128.9 | Q18: =SUM(Q19:Q23) -> 8297611.1 | R18: =SUM(R19:R23) -> 8245274.6 | S18: =SUM(S19:S23) -> 9121181.6 | T18: =SUM(T19:T23) -> 8802585.1 | U18: =SUM(U19:U23) -> 8895621 | V18: =SUM(V19:V23) -> 9187442.8 | ... Z18: =SUM(Z19:Z23) -> 8959262.6 | AA18: =SUM(O18,P18,Q18,R18,S18,T18,U18,V18,W18,X18,Y18,Z18) -> 1.0587893e+08 | AB18: =SUM(AB19:AB23) -> 9589052 | AC18: =SUM(AC19:AC23) -> 9239180.3 | AD18: =SUM(AD19:AD23) -> 8871197.8 | AE18: =SUM(AE19:AE23) -> 8749407.4 | AF18: =SUM(AF19:AF23) -> 9882542.9 | AG18: =SUM(AG19:AG23) -> 9586720.2 | AH18: =SUM(AH19:AH23) -> 9864435.5 | AI18: =SUM(AI19:AI23) -> 10235518 | ... AM18: =SUM(AM19:AM23) -> 9969579.3 | AN18: =SUM(AB18,AC18,AD18,AE18,AF18,AG18,AH18,AI18,AJ18,AK18,AL18,AM18) -> 1.1592359e+08
A19: Fletes | B19: =B163 -> 494367.56 | C19: =C163 -> 396171.07 | D19: =D163 -> 343227.86 | E19: =E163 -> 535156.62 | F19: =F163 -> 519993.99 | G19: =G163 -> 560717.72 | H19: =H163 -> 570275.01 | I19: =I163 -> 764149.51 | ... M19: =M163 -> 653773.02 | N19: =SUM(B19,C19,D19,E19,F19,G19,H19,I19,J19,K19,L19,M19) -> 6810595.6 | O19: =O163 -> 702680.18 | P19: =P163 -> 616591.51 | Q19: =Q163 -> 491322.68 | R19: =R163 -> 672682.58 | S19: =S163 -> 792079.78 | T19: =T163 -> 671392.71 | U19: =U163 -> 886780.02 | V19: =V163 -> 955186.89 | ... Z19: =Z163 -> 817216.27 | AA19: =SUM(O19,P19,Q19,R19,S19,T19,U19,V19,W19,X19,Y19,Z19) -> 9071886.7 | AB19: =AB163 -> 877195.11 | AC19: =AC163 -> 770718.45 | AD19: =AD163 -> 618631.79 | AE19: =AE163 -> 825603.44 | AF19: =AF163 -> 984452.05 | AG19: =AG163 -> 838640.8 | AH19: =AH163 -> 1092419.8 | AI19: =AI163 -> 1178284.6 | ... AM19: =AM163 -> 1013921.6 | AN19: =SUM(AB19,AC19,AD19,AE19,AF19,AG19,AH19,AI19,AJ19,AK19,AL19,AM19) -> 11258737 | AQ19: =SUM(B19,C19,D19,E19,F19:M19) -> 6810595.6 | AR19: =N19/N$18 -> 0.059737899
A20: Directos | B20: =B160 -> 3242912.5 | C20: =C160 -> 2305460.2 | D20: =D160 -> 1787305.3 | E20: =E160 -> 2025486 | F20: =F160 -> 2081617.5 | G20: =G160 -> 2047912.4 | H20: =H160 -> 1940260.9 | I20: =I160 -> 1795060.9 | ... M20: =M160 -> 1388185.9 | N20: =SUM(B20,C20,D20,E20,F20,G20,H20,I20,J20,K20,L20,M20) -> 22778759 | O20: =O160 -> 1388185.9 | P20: =P160 -> 1388185.9 | Q20: =Q160 -> 1388185.9 | R20: =R160 -> 1388185.9 | S20: =S160 -> 1388185.9 | T20: =T160 -> 1388185.9 | U20: =U160 -> 1388185.9 | V20: =V160 -> 1388185.9 | ... Z20: =Z160 -> 1388185.9 | AA20: =SUM(O20,P20,Q20,R20,S20,T20,U20,V20,W20,X20,Y20,Z20) -> 16658230 | AB20: =AB160 -> 1388185.9 | AC20: =AC160 -> 1388185.9 | AD20: =AD160 -> 1388185.9 | AE20: =AE160 -> 1388185.9 | AF20: =AF160 -> 1388185.9 | AG20: =AG160 -> 1388185.9 | AH20: =AH160 -> 1388185.9 | AI20: =AI160 -> 1388185.9 | ... AM20: =AM160 -> 1388185.9 | AN20: =SUM(AB20,AC20,AD20,AE20,AF20,AG20,AH20,AI20,AJ20,AK20,AL20,AM20) -> 16658230 | AQ20: =SUM(B20,C20,D20,E20,F20:M20) -> 22778759 | AR20: =N20/N$18 -> 0.19979974
A21: Indirectos | B21: =B161 -> 2217469.1 | C21: =C161 -> 2265220.1 | D21: =D161 -> 2320283.3 | E21: =E161 -> 2494447.6 | F21: =F161 -> 2406419.4 | G21: =G161 -> 2922932.4 | H21: =H161 -> 2546501 | I21: =I161 -> 2776624.5 | ... M21: =M161 -> 2714790.3 | N21: =SUM(B21,C21,D21,E21,F21,G21,H21,I21,J21,K21,L21,M21) -> 30824400 | O21: =O161 -> 2911985 | P21: =P161 -> 2851722.9 | Q21: =Q161 -> 2764034.7 | R21: =R161 -> 2890986.7 | S21: =S161 -> 3006239.7 | T21: =T161 -> 2856384.1 | U21: =U161 -> 3007155.2 | V21: =V161 -> 3055040 | ... Z21: =Z161 -> 2946184.6 | AA21: =SUM(O21,P21,Q21,R21,S21,T21,U21,V21,W21,X21,Y21,Z21) -> 35138300 | AB21: =AB161 -> 3082509.7 | AC21: =AC161 -> 3007976.1 | AD21: =AD161 -> 2901515.4 | AE21: =AE161 -> 3046395.6 | AF21: =AF161 -> 3191481.8 | AG21: =AG161 -> 3102917.6 | AH21: =AH161 -> 3280562.9 | AI21: =AI161 -> 3340668.2 | ... AM21: =AM161 -> 3212110.5 | AN21: =SUM(AB21,AC21,AD21,AE21,AF21,AG21,AH21,AI21,AJ21,AK21,AL21,AM21) -> 37814442 | AQ21: =SUM(B21,C21,D21,E21,F21:M21) -> 30824400 | AR21: =N21/N$18 -> 0.27037061
A22: Ventas | B22: =B164 -> 1160984.1 | C22: =C164 -> 1314802.3 | D22: =D164 -> 1630274.2 | E22: =E164 -> 1744545.4 | F22: =F164 -> 2118876.6 | G22: =G164 -> 1773434.4 | H22: =H164 -> 2415689.7 | I22: =I164 -> 1507233.9 | ... M22: =M164 -> 1632497.8 | N22: =SUM(B22,C22,D22,E22,F22,G22,H22,I22,J22,K22,L22,M22) -> 19918588 | O22: =O164 -> 1797219 | P22: =P164 -> 1680976.5 | Q22: =Q164 -> 1616293.8 | R22: =R164 -> 1225418.9 | S22: =S164 -> 1846776.1 | T22: =T164 -> 1818836.8 | U22: =U164 -> 1669816.4 | V22: =V164 -> 1833945.3 | ... Z22: =Z164 -> 1875586.4 | AA22: =SUM(O22,P22,Q22,R22,S22,T22,U22,V22,W22,X22,Y22,Z22) -> 20987892 | AB22: =AB164 -> 2231079.7 | AC22: =AC164 -> 2079964.4 | AD22: =AD164 -> 1995876.9 | AE22: =AE164 -> 1487739.5 | AF22: =AF164 -> 2290465.3 | AG22: =AG164 -> 2253320.1 | AH22: =AH164 -> 2057314.5 | AI22: =AI164 -> 2268116.3 | ... AM22: =AM164 -> 2322492 | AN22: =SUM(AB22,AC22,AD22,AE22,AF22,AG22,AH22,AI22,AJ22,AK22,AL22,AM22) -> 25949136 | AQ22: =SUM(B22,C22,D22,E22,F22:M22) -> 19918588 | AR22: =N22/N$18 -> 0.17471227
A23: Admin | B23: =B165 -> 4903313 | C23: =C165 -> 3759869.5 | D23: =D165 -> 4754130.9 | E23: =E165 -> 2869759.6 | F23: =F165 -> 3273861.1 | G23: =G165 -> 2087472 | H23: =H165 -> 2579457.4 | I23: =I165 -> 1903884.7 | ... M23: =M165 -> 1885488.6 | N23: =SUM(B23,C23,D23,E23,F23,G23,H23,I23,J23,K23,L23,M23) -> 33675610 | O23: =O165 -> 2073000.2 | P23: =P165 -> 2058652.1 | Q23: =Q165 -> 2037774 | R23: =R165 -> 2068000.6 | S23: =S165 -> 2087900.2 | T23: =T165 -> 2067785.6 | U23: =U165 -> 1943683.5 | V23: =V165 -> 1955084.7 | ... Z23: =Z165 -> 1932089.6 | AA23: =SUM(O23,P23,Q23,R23,S23,T23,U23,V23,W23,X23,Y23,Z23) -> 24022623 | AB23: =AB165 -> 2010081.6 | AC23: =AC165 -> 1992335.5 | AD23: =AD165 -> 1966987.8 | AE23: =AE165 -> 2001483 | AF23: =AF165 -> 2027957.8 | AG23: =AG165 -> 2003655.9 | AH23: =AH165 -> 2045952.4 | AI23: =AI165 -> 2060263.2 | ... AM23: =AM165 -> 2032869.4 | AN23: =SUM(AB23,AC23,AD23,AE23,AF23,AG23,AH23,AI23,AJ23,AK23,AL23,AM23) -> 24243046 | AQ23: =SUM(B23,C23,D23,E23,F23:M23) -> 33675610 | AR23: =N23/N$18 -> 0.29537948
A25: Efectivo generado por las operaciones | B25: =+B6-B11 -> 0 | C25: =+C6-C11 -> 0 | D25: =+D6-D11 -> 0 | E25: =+E6-E11 -> 0 | F25: =+F6-F11 -> -1144719.4 | G25: =+G6-G11 -> -1272887.1 | H25: =+H6-H11 -> -58721.611 | I25: =+I6-I11 -> 3028285.7 | ... M25: =+M6-M11 -> 3904674.8 | N25: =SUM(B25,C25,D25,E25,F25,G25,H25,I25,J25,K25,L25,M25) -> 15550514 | O25: =+O6-O11 -> 3109617.5 | P25: =+P6-P11 -> 2190048.2 | Q25: =+Q6-Q11 -> 3729120.1 | R25: =+R6-R11 -> 4468012.1 | S25: =+S6-S11 -> 2174583.7 | T25: =+T6-T11 -> -241120.19 | U25: =+U6-U11 -> 3306471.5 | V25: =+V6-V11 -> 4979840.6 | ... Z25: =+Z6-Z11 -> 6268728.4 | AA25: =SUM(O25,P25,Q25,R25,S25,T25,U25,V25,W25,X25,Y25,Z25) -> 46771728 | AB25: =+AB6-AB11 -> 5389307.7 | AC25: =+AC6-AC11 -> 4243541 | AD25: =+AD6-AD11 -> 6253589.1 | AE25: =+AE6-AE11 -> 7205504.2 | AF25: =+AF6-AF11 -> 4311318.2 | AG25: =+AG6-AG11 -> 1247348.4 | AH25: =+AH6-AH11 -> 5229713.4 | AI25: =+AI6-AI11 -> 7465391.7 | ... AM25: =+AM6-AM11 -> 8948999.5 | AN25: =SUM(AB25,AC25,AD25,AE25,AF25,AG25,AH25,AI25,AJ25,AK25,AL25,AM25) -> 74689577
A26: Gastos Financieros | F26: 1645386.8 | G26: 1200000 | H26: ='Interest Expense'!R31 -> 860955.61 | I26: ='Interest Expense'!S31 -> 1267197.2 | J26: ='Interest Expense'!T31 -> 1435839.3 | K26: ='Interest Expense'!U31 -> 1503784.3 | L26: ='Interest Expense'!V31 -> 1497283.3 | M26: ='Interest Expense'!W31 -> 1490677.2 | N26: =SUM(B26,C26,D26,E26,F26,G26,H26,I26,J26,K26,L26,M26) -> 10901124 | O26: ='Interest Expense'!Y31 -> 1483963.4 | P26: ='Interest Expense'!Z31 -> 1477139.7 | Q26: ='Interest Expense'!AA31 -> 1456401.4 | R26: ='Interest Expense'!AB31 -> 1430517.1 | S26: ='Interest Expense'!AC31 -> 1409802 | T26: ='Interest Expense'!AD31 -> 1385909.2 | U26: ='Interest Expense'!AE31 -> 1365318.4 | V26: ='Interest Expense'!AF31 -> 1341888.3 | ... Z26: ='Interest Expense'!AJ31 -> 1258523.4 | AA26: =SUM(O26,P26,Q26,R26,S26,T26,U26,V26,W26,X26,Y26,Z26) -> 16508198 | AB26: ='Interest Expense'!AM31 -> 705709.12 | AC26: ='Interest Expense'!AN31 -> 685472.38 | AD26: ='Interest Expense'!AO31 -> 665122.74 | AE26: ='Interest Expense'!AP31 -> 644657.74 | AF26: ='Interest Expense'!AQ31 -> 624074.88 | AG26: ='Interest Expense'!AR31 -> 603371.62 | AH26: ='Interest Expense'!AS31 -> 582545.34 | AI26: ='Interest Expense'!AT31 -> 561593.37 | ... AL26: ='Interest Expense'!AW31 -> 501626.27 | AM26: ='Interest Expense'!AY31 -> 481367.22 | AN26: =SUM(AB26,AC26,AD26,AE26,AF26,AG26,AH26,AI26,AJ26,AK26,AL26,AM26) -> 7119025.5 | AQ26: =SUM(B26,C26,D26,E26,F26:M26) -> 10901124 | AR26: 0
A27: Impuestos | B27: =+B28-B29-B30-B31 -> 0 | C27: =+C28-C29-C30-C31 -> 0 | D27: =+D28-D29-D30-D31 -> 0 | E27: =+E28-E29-E30-E31 -> 0 | F27: =+F28-F29-F30-F31 -> 0 | G27: =+G28-G29-G30-G31 -> 0 | H27: =+H28-H29-H30-H31 -> 0 | I27: =+I28-I29-I30-I31 -> 0 | ... N27: =+N28-N29-N30-N31 -> 0 | AA27: =+AA28-AA29-AA30-AA31 -> 0 | AN27: =+AN28-AN29-AN30-AN31 -> 0
A28: IVA recuperado / Capital | N28: =SUM(B28,C28,D28,E28,F28,G28,H28,I28,J28,K28,L28,M28) -> 0 | AA28: =SUM(O28,P28,Q28,R28,S28,T28,U28,V28,W28,X28,Y28,Z28) -> 0 | AN28: =SUM(AB28,AC28,AD28,AE28,AF28,AG28,AH28,AI28,AJ28,AK28,AL28,AM28) -> 0 | AQ28: =SUM(B28,C28,D28,E28,F28:M28) -> 0
A29: Retenciones de Impuestos | N29: =SUM(B29,C29,D29,E29,F29,G29,H29,I29,J29,K29,L29,M29) -> 0 | AA29: =SUM(O29,P29,Q29,R29,S29,T29,U29,V29,W29,X29,Y29,Z29) -> 0 | AN29: =SUM(AB29,AC29,AD29,AE29,AF29,AG29,AH29,AI29,AJ29,AK29,AL29,AM29) -> 0 | AQ29: =SUM(B29,C29,D29,E29,F29:M29) -> 0
A30: ISR pago provisional | E30: ='Cashflow (ROLLING) CAP'!E172 -> 0 | F30: ='Cashflow (ROLLING) CAP'!F172 -> 0 | G30: ='Cashflow (ROLLING) CAP'!G172 -> 0 | H30: ='Cashflow (ROLLING) CAP'!H172 -> 0 | I30: ='Cashflow (ROLLING) CAP'!I172 -> 0 | J30: ='Cashflow (ROLLING) CAP'!J172 -> 0 | K30: ='Cashflow (ROLLING) CAP'!K172 -> 0 | L30: ='Cashflow (ROLLING) CAP'!L172 -> 0 | M30: ='Cashflow (ROLLING) CAP'!M172 -> 0 | N30: =SUM(B30,C30,D30,E30,F30,G30,H30,I30,J30,K30,L30,M30) -> 0 | AA30: =SUM(O30,P30,Q30,R30,S30,T30,U30,V30,W30,X30,Y30,Z30) -> 0 | AN30: =SUM(AB30,AC30,AD30,AE30,AF30,AG30,AH30,AI30,AJ30,AK30,AL30,AM30) -> 0 | AQ30: =SUM(B30,C30,D30,E30,F30:M30) -> 0
A31: Deuda IVA | B31: 0 | C31: 0 | D31: 0 | N31: =SUM(B31,C31,D31,E31,F31,G31,H31,I31,J31,K31,L31,M31) -> 0 | AA31: =SUM(O31,P31,Q31,R31,S31,T31,U31,V31,W31,X31,Y31,Z31) -> 0 | AN31: =SUM(AB31,AC31,AD31,AE31,AF31,AG31,AH31,AI31,AJ31,AK31,AL31,AM31) -> 0 | AQ31: =SUM(B31,C31,D31,E31,F31:M31) -> 0
A34: FLUJO NETO DE OPERACIÓN | B34: =+B25-B26+B27 -> 0 | C34: =+C25-C26+C27 -> 0 | D34: =+D25-D26+D27 -> 0 | E34: =+E25-E26+E27 -> 0 | F34: =+F25-F26+F27 -> -2790106.2 | G34: =+G25-G26+G27 -> -2472887.1 | H34: =+H25-H26+H27 -> -919677.22 | I34: =+I25-I26+I27 -> 1761088.5 | ... AN34: =+AN25-AN26+AN27 -> 67570552
A36: CAPEX | E36: 200000 | F36: 200000 | G36: 200000 | H36: 750000 | I36: 750000 | J36: 750000 | K36: 750000 | L36: 750000 | M36: 750000 | N36: =SUM(B36,C36,D36,E36,F36,G36,H36,I36,J36,K36,L36,M36) -> 5100000 | O36: 750000 | P36: 750000 | Q36: 750000 | R36: 750000 | S36: 750000 | T36: 750000 | U36: 750000 | V36: 750000 | W36: 750000 | X36: 750000 | Y36: 750000 | Z36: 750000 | AA36: =SUM(O36,P36,Q36,R36,S36,T36,U36,V36,W36,X36,Y36,Z36) -> 9000000 | AB36: 300000 | AC36: 300000 | AD36: 300000 | AE36: 300000 | AF36: 300000 | AG36: 300000 | AH36: 300000 | AI36: 300000 | AJ36: 300000 | AK36: 300000 | AL36: 300000 | AM36: 300000 | AN36: =SUM(AB36,AC36,AD36,AE36,AF36,AG36,AH36,AI36,AJ36,AK36,AL36,AM36) -> 3600000 | AQ36: =SUM(B36,C36,D36,E36,F36:M36) -> 5100000
A37: Otras Deudas Pre-Operación | G37: 150000 | H37: 150000 | I37: 150000 | J37: 50000 | K37: 50000 | L37: 50000 | M37: 50000 | N37: =SUM(B37,C37,D37,E37,F37,G37,H37,I37,J37,K37,L37,M37) -> 650000 | O37: 25000 | P37: 25000 | Q37: 25000 | R37: 25000 | S37: 25000 | T37: 25000 | U37: 25000 | V37: 25000 | W37: 25000 | X37: 25000 | Y37: 25000 | Z37: 25000 | AA37: =SUM(O37,P37,Q37,R37,S37,T37,U37,V37,W37,X37,Y37,Z37) -> 300000 | AN37: =SUM(AB37,AC37,AD37,AE37,AF37,AG37,AH37,AI37,AJ37,AK37,AL37,AM37) -> 0 | AQ37: =SUM(B37,C37,D37,E37,F37:M37) -> 650000
A39: FLUJO NETO DE INVERSIÓN | B39: =-B36-B37 -> 0 | C39: =-C36-C37 -> 0 | D39: =-D36-D37 -> 0 | E39: =-E36-E37 -> -200000 | F39: =-F36-F37 -> -200000 | G39: =-G36-G37 -> -350000 | H39: =-H36-H37 -> -900000 | I39: =-I36-I37 -> -900000 | ... T39: =-T36-T37 -> -775000 | AA39: =-AA36-AA37 -> -9300000 | AN39: =-AN36-AN37 -> -3600000
E41: 30000000
N44: =SUM(B44,C44,D44,E44,F44,G44,H48,I48,J48,K44,L44,M44) -> 24071501 | AA44: =SUM(O44,P44,Q44,R44,S44,T44,U48,V48,W48,X44,Y44,Z44) -> 0 | AN44: =SUM(AB44,AC44,AD44,AE44,AF44,AG44,AH48,AI48,AJ48,AK44,AL44,AM44) -> 0
A45: Disposición de Deuda | H45: 33000000 | I45: 14000000 | J45: 6000000 | N45: =SUM(B45,C45,D45,E45,F45,G45,H45,I45,J45,K45,L45,M45) -> 53000000 | AA45: =SUM(O45,P45,Q45,R45,S45,T45,U45,V45,W45,X45,Y45,Z45) -> 0 | AN45: =SUM(AB45,AC45,AD45,AE45,AF45,AG45,AH45,AI45,AJ45,AK45,AL45,AM45) -> 0
A46: Pago de Deuda
A47: IVA | I47: 1500000 | J47: 1500000 | K47: 1500000 | L47: 1500000 | M47: 1500000 | N47: =SUM(B47,C47,D47,E47,F47,G47,H47,I47,J47,K47,L47,M47) -> 7500000 | O47: 1500000 | P47: 1500000 | Q47: 1500000 | R47: 1500000 | S47: 1500000 | AA47: =SUM(O47,P47,Q47,R47,S47,T47,U47,V47,W47,X47,Y47,Z47) -> 7500000 | AN47: =SUM(AB47,AC47,AD47,AE47,AF47,AG47,AH47,AI47,AJ47,AK47,AL47,AM47) -> 0
A48: Capital X | H48: ='Linea Sesajal'!E43 -> 11503037 | I48: ='Linea Sesajal'!F43 -> 10695606 | J48: ='Linea Sesajal'!G43 -> 1872856.9 | N48: =SUM(B48,C48,D48,E48,F48,G48,H48,I48,J48,K48,L48,M48) -> 24071501 | AA48: =SUM(O48,P48,Q48,R48,S48,T48,U48,V48,W48,X48,Y48,Z48) -> 0 | AN48: =SUM(AB48,AC48,AD48,AE48,AF48,AG48,AH48,AI48,AJ48,AK48,AL48,AM48) -> 0
A49: Capix | K49: 500000 | L49: 500000 | M49: 500000 | N49: =SUM(B49,C49,D49,E49,F49,G49,H49,I49,J49,K49,L49,M49) -> 1500000 | O49: 500000 | P49: 500000 | Q49: 500000 | R49: 500000 | S49: 500000 | T49: 500000 | U49: 500000 | V49: 500000 | W49: 500000 | X49: 500000 | Y49: 500000 | Z49: 500000 | AA49: =SUM(O49,P49,Q49,R49,S49,T49,U49,V49,W49,X49,Y49,Z49) -> 6000000 | AN49: =SUM(AB49,AC49,AD49,AE49,AF49,AG49,AH49,AI49,AJ49,AK49,AL49,AM49) -> 0
A50: Nuvari | H50: 16000000 | N50: =SUM(B50,C50,D50,E50,F50,G50,H50,I50,J50,K50,L50,M50) -> 16000000 | AA50: =SUM(O50,P50,Q50,R50,S50,T50,U50,V50,W50,X50,Y50,Z50) -> 0 | AN50: =SUM(AB50,AC50,AD50,AE50,AF50,AG50,AH50,AI50,AJ50,AK50,AL50,AM50) -> 0
A51: Sesajal | N51: =SUM(B51,C51,D51,E51,F51,G51,H51,I51,J51,K51,L51,M51) -> 0 | O51: 1105000 | P51: 1105000 | Q51: 1105000 | R51: 1105000 | S51: 1105000 | T51: 1105000 | U51: 1105000 | V51: 1105000 | W51: 1105000 | X51: 1105000 | Y51: 1105000 | Z51: 1105000 | AA51: =SUM(O51,P51,Q51,R51,S51,T51,U51,V51,W51,X51,Y51,Z51) -> 13260000 | AB51: 1105000 | AC51: 1105000 | AD51: 1105000 | AE51: 1105000 | AF51: 1105000 | AG51: 1105000 | AH51: 1105000 | AI51: 1105000 | AJ51: 1105000 | AK51: 1105000 | AL51: 1105000 | AM51: 1105000 | AN51: =SUM(AB51,AC51,AD51,AE51,AF51,AG51,AH51,AI51,AJ51,AK51,AL51,AM51) -> 13260000
A52: Creditos Otros | B52: {=TRANSPOSE('CREDITOS'!CF56:CF67)} -> 709985.63 | C52: 651234.5 | D52: 651362.66 | E52: 651493.63 | F52: 165660.05 | G52: 165796.65 | H52: 152417.85 | I52: 152560.52 | J52: 152706.27 | K52: 152855.19 | L52: 153007.33 | M52: 153162.76 | N52: =SUM(B52,C52,D52,E52,F52,G52,H52,I52,J52,K52,L52,M52) -> 3912243 | O52: {=TRANSPOSE('CREDITOS'!CF68:CF79)} -> 153321.57 | P52: 153483.81 | Q52: 153649.57 | R52: 153818.92 | S52: 153991.95 | T52: 154168.72 | U52: 154349.32 | V52: 154533.83 | W52: 154722.34 | X52: 154914.93 | Y52: 155111.7 | Z52: 105312.73 | AA52: =SUM(O52,P52,Q52,R52,S52,T52,U52,V52,W52,X52,Y52,Z52) -> 1801379.4 | AB52: {=TRANSPOSE('CREDITOS'!CF80:CF91)} -> 105518.12 | AC52: 105727.96 | AD52: 105942.34 | AE52: 106161.37 | AF52: 106385.14 | AG52: 106613.77 | AH52: 106847.34 | AI52: 107085.98 | AJ52: 11496.458 | AK52: 11745.548 | AL52: 12000.034 | AM52: 12260.035 | AN52: =SUM(AB52,AC52,AD52,AE52,AF52,AG52,AH52,AI52,AJ52,AK52,AL52,AM52) -> 897784.1
...

Sheet IS (ROLLING)
BK7: 14603982 | BL7: 8000000 | BM7: 8000000 | BN7: 8000000 | BO7: 8000000 | BP7: 8000000 | BQ7: 8000000 | BR7: 8000000 | BS7: 8000000 | BT7: 8000000 | BU7: 23085702 | BV7: 8000000 | BW7: 8000000 | BX7: 8000000 | BY7: 8000000 | BZ7: 8000000 | CA7: 8000000 | CB7: 8000000 | CC7: 8000000 | CD7: 8000000 | CE7: 19370357 | CF7: 8000000 | CG7: 8000000 | CH7: 8000000 | CI7: 8000000 | CJ7: 8000000 | CK7: 8000000 | CL7: 8000000 | CM7: 8000000 | CN7: 8000000 | CO7: 23764811 | CP7: 8000000 | CQ7: 8000000 | CR7: 8000000 | CS7: 8000000 | CT7: 8000000 | CU7: 8000000 | CV7: 8000000 | CW7: 8000000 | CX7: 8000000 | CY7: 22053812
B9: INCOME STATEMENT (ROLLING FCST) | AP9: =(AP18/AB18)-100% -> 0.25 | BD9: =(BD18/AP18)-100% -> 0.24105793
B10: PERIODO | BD10: =(BD18/AB18)-100% -> 0.55132241
B11: MES | C11: 1 | D11: 2 | E11: 3 | F11: 4 | G11: 5 | H11: 6 | I11: 7 | J11: 8 | K11: 9 | L11: 10 | M11: 11 | N11: 12 | P11: 1 | Q11: 2 | R11: 3 | S11: 4 | T11: 5 | U11: 6 | V11: 7 | W11: 8 | X11: 9 | Y11: 10 | Z11: 11 | AA11: 12 | AB11: 2025 | AD11: 1 | AE11: 2 | AF11: 3 | AG11: 4 | AH11: 5 | AI11: 6 | AJ11: 7 | AK11: 8 | AL11: 9 | AM11: 10 | AN11: 11 | AO11: 12 | AP11: 2026 | AR11: 1 | AS11: 2 | AT11: 3 | AU11: 4 | AV11: 5 | AW11: 6 | AX11: 7 | AY11: 8 | AZ11: 9 | BA11: 10 | BB11: 11 | BC11: 12 | BD11: 2027 | BE11: 2028 | BF11: 2028 | BG11: Comentarios
B12: QTR | C12: 1 | D12: 1 | E12: 1 | F12: 2 | G12: 2 | H12: 2 | I12: 3 | J12: 3 | K12: 3 | L12: 4 | M12: 4 | N12: 4 | P12: 1 | Q12: 1 | R12: 1 | S12: 2 | T12: 2 | U12: 2 | V12: 3 | W12: 3 | X12: 3 | Y12: 4 | Z12: 4 | AA12: 4 | AD12: 1 | AE12: 1 | AF12: 1 | AG12: 2 | AH12: 2 | AI12: 2 | AJ12: 3 | AK12: 3 | AL12: 3 | AM12: 4 | AN12: 4 | AO12: 4 | AR12: 1 | AS12: 1 | AT12: 1 | AU12: 2 | AV12: 2 | AW12: 2 | AX12: 3 | AY12: 3 | AZ12: 3 | BA12: 4 | BB12: 4 | BC12: 4
B13: YEAR | C13: 2024 | D13: 2024 | E13: 2024 | F13: 2024 | G13: 2024 | H13: 2024 | I13: 2024 | J13: 2024 | K13: 2024 | L13: 2024 | M13: 2024 | N13: 2024 | P13: 2025 | Q13: 2025 | R13: 2025 | S13: 2025 | T13: 2025 | U13: 2025 | V13: 2025 | W13: 2025 | X13: 2025 | Y13: 2025 | Z13: 2025 | AA13: 2025 | AD13: 2026 | AE13: 2026 | AF13: 2026 | AG13: 2026 | AH13: 2026 | AI13: 2026 | AJ13: 2026 | AK13: 2026 | AL13: 2026 | AM13: 2026 | AN13: 2026 | AO13: 2026 | AR13: 2027 | AS13: 2027 | AT13: 2027 | AU13: 2027 | AV13: 2027 | AW13: 2027 | AX13: 2027 | AY13: 2027 | AZ13: 2027 | BA13: 2027 | BB13: 2027 | BC13: 2027
B15: Maquila | P15: 9677100.6 | Q15: 8226802.9 | R15: 5356720.1 | S15: 13035711 | T15: 11700675 | U15: 8685547.9 | V15: 15512994 | W15: 16143512 | X15: 14196904 | Y15: 12303555 | Z15: 10392541 | AA15: 12161452 | AB15: =SUM(P15:AA15) -> 1.3739352e+08 | AD15: =P15*1.25 -> 12096376 | AE15: =Q15*1.25 -> 10283504 | AF15: =R15*1.25 -> 6695900.2 | AG15: =S15*1.25 -> 16294639 | AH15: =T15*1.25 -> 14625844 | AI15: =U15*1.25 -> 10856935 | AJ15: =V15*1.25 -> 19391243 | AK15: =W15*1.25 -> 20179390 | ... AO15: =AA15*1.25 -> 15201815 | AP15: =SUM(AD15:AO15) -> 1.7174189e+08 | AR15: =AD15*1.2 -> 14515651 | AS15: =AE15*1.2 -> 12340204 | AT15: =AF15*1.2 -> 8035080.2 | AU15: =AG15*1.2 -> 19553566 | AV15: =AH15*1.2 -> 17551013 | AW15: =AI15*1.2 -> 13028322 | AX15: =AJ15*1.2 -> 23269491 | AY15: =AK15*1.2 -> 24215269 | ... BC15: =AO15*1.2 -> 18242178 | BD15: =SUM(AR15:BC15) -> 2.0609027e+08 | BE15: =BD15*1.1 -> 2.266993e+08 | BF15: =BE15*1.1 -> 2.4936923e+08 | BG15: La proyección de ingresos por maquila contempla ingresos con Grisi, KPS y Laboratorios Best. Ver detalle de CXC y principales clientes contemplados en esta proyección.
