Workbook

Sheet REPORTE_CORTOS
A1: CODIGO | B1: 51CBLO01 | C1: 51CBOM04 | D1: 51CBOM05 | E1: 51CPAM01 | F1: 51CPAZ03 | G1: 51CPAZ04 | H1: 51CPAZ05 | I1: 51CPBD01 | J1: 51CPBD02 | K1: 51CPBR01 | L1: 51CPBW01 | M1: 51CPCA01 | N1: 51CPCB01 | O1: 51CPCD01 | P1: 51CPCS01 | Q1: 51CPCS02 | R1: 51CPCV01 | S1: 51CPDG05 | T1: 51CPDG06 | U1: 51CPDL01 | V1: 51CPDN01 | W1: 51CPFB01 | X1: 51CPFBB01 | Y1: 51CPFIT01 | Z1: 51CPFIT02 | AA1: 51CPFIT03 | AB1: 51CPFP01 | AC1: 51CPFP02 | AD1: 51CPGBS01 | AE1: 51CPGM01 | AF1: 51CPGM02 | AG1: 51CPGMFA01 | AH1: 51CPKM01 | AI1: 51CPKM02 | AJ1: 51CPLM01 | AK1: 51CPLP01 | AL1: 51CPLR01 | AM1: 51CPMB01 | AN1: 51CPMM01 | AO1: 51CPMM02 | AP1: 51CPMS01 | AQ1: 51CPOM01 | AR1: 51CPOM02 | AS1: 51CPOM03 | AT1: 51CPPBS01 | AU1: 51CPPH01 | AV1: 51CPPMS01 | AW1: 51CPRM01 | AX1: 51CPRM02 | AY1: 51CPVAF01 | AZ1: 51CPVB01 | BA1: 51CPVB02 | BB1: 51CPVF01 | BC1: 51CPVT03 | BD1: 51CPVT05 | BE1: 51CPWB01 | BF1: 51CPWP01 | BG1: 51CPWQU01 | BH1: 51CPWR01 | BI1: 51GLVA04 | BJ1: 51JBMP01 | BK1: 51JBNC01 | BL1: 51PLAB01 | BM1: 51PLAB02 | BN1: 51PLBC01 | BO1: 51PLBC02 | BP1: 51PLBCL01 | BQ1: 51PLBCL02 | BR1: 51PLBCL03 | BS1: 51PLBCS01 | BT1: 51PLBFK01 | BU1: 51PLBFK02 | BV1: 51PLBK01 | BW1: 51PLBMF01 | BX1: 51PLBMF03 | BY1: 51PLBMF04 | BZ1: 51PLBMM01 | CA1: 51PLBMM03 | CB1: 51PLBMM04 | CC1: 51PLBMY01 | CD1: 51PLBVP01 | CE1: 51PLC201 | CF1: 51PLC202 | CG1: 51PLC203 | CH1: 51PLCB03 | CI1: 51PLCB04 | CJ1: 51PLCB06 | CK1: 51PLCCDS01 | CL1: 51PLCHS01 | CM1: 51PLCL01 | CN1: 51PLCM01 | CO1: 51PLCN01 | CP1: 51PLCOH01 | CQ1: 51PLCR01 | CR1: 51PLCR02 | CS1: 51PLCRH01 | CT1: 51PLCV01 | CU1: 51PLCV03 | CV1: 51PLCX01 | CW1: 51PLCXA01 | CX1: 51PLCXA02 | CY1: 51PLCXM01 | CZ1: 51PLDL01 | DA1: 51PLDL02 | DB1: 51PLDL03 | DC1: 51PLDL04 | DD1: 51PLDL05 | DE1: 51PLEF01 | DF1: 51PLEL01 | DG1: 51PLFC01 | DH1: 51PLFP01 | DI1: 51PLFP02 | DJ1: 51PLFX01 | DK1: 51PLFX02 | DL1: 51PLFX04 | DM1: 51PLGRH01 | DN1: 51PLGS01 | DO1: 51PLGY01 | DP1: 51PLHG01 | DQ1: 51PLHG02 | DR1: 51PLHG03 | DS1: 51PLHG07 | DT1: 51PLHG09 | DU1: 51PLHG10 | DV1: 51PLHG11 | DW1: 51PLHG12 | DX1: 51PLHG18 | DY1: 51PLHG20 | DZ1: 51PLHG21 | EA1: 51PLHG23 | EB1: 51PLHG24 | EC1: 51PLHG25 | ED1: 51PLHG26 | EE1: 51PLHG27 | EF1: 51PLHG28 | EG1: 51PLHG29 | EH1: 51PLHG30 | EI1: 51PLHG31 | EJ1: 51PLHG32 | EK1: 51PLHG33 | EL1: 51PLHG34 | EM1: 51PLHG35 | EN1: 51PLHG36 | EO1: 51PLHK01 | EP1: 51PLHK02 | EQ1: 51PLHK03 | ER1: 51PLKL01 | ES1: 51PLLC01 | ET1: 51PLPC01 | EU1: 51PLPW01 | EV1: 51PLPW02 | EW1: 51PLPW03 | EX1: 51PLSF01 | EY1: 51PLTF01 | EZ1: 51PLVC01 | FA1: 51TBAC01 | FB1: 51TBAFS01 | FC1: 51TBAP01 | FD1: 51TBBCS01 | FE1: 51TBBF02 | FF1: 51TBBH01 | FG1: 51TBBM01 | FH1: 51TBCA05 | FI1: 51TBCB01 | FJ1: 51TBCBS01 | FK1: 51TBCG01 | FL1: 51TBCMZS01 | FM1: 51TBCR01 | FN1: 51TBCV01 | FO1: 51TBECBA01 | FP1: 51TBECGA01 | FQ1: 51TBEKDA01 | FR1: 51TBEMKA01 | FS1: 51TBEVCS01 | FT1: 51TBEX01 | FU1: 51TBEX03 | FV1: 51TBKY01 | FW1: 51TBLC01 | FX1: 51TBMC01 | FY1: 51TBME01 | FZ1: 51TBME03 | GA1: 51TBMF01 | GB1: 51TBML01 | GC1: 51TBMM01 | GD1: 51TBMN01 | GE1: 51TBMVA01 | GF1: 51TBMZ01 | GG1: 51TBPF01 | GH1: 51TBTM01 | GI1: 51TBTM05 | GJ1: 51TBVB01 | GK1: 51TBVCA01 | GL1: 51TBVCS01 | GM1: 51TBVDS01 | GN1: 51TBVK01 | GO1: 51TBVRS01 | GP1: 51TBZA01 | GQ1: 51TBZN01 | GR1: Descripción | GS1: LT | GT1: Proveedor | GU1: Tipo | GV1: A1 | GW1: A2 | GX1: A3 | GY1: Type | GZ1: 45887 | HA1: =WORKDAY.INTL(GZ1,1,11) -> 45888 | HB1: =WORKDAY.INTL(HA1,1,11) -> 45889 | HC1: =WORKDAY.INTL(HB1,1,11) -> 45890 | HD1: =WORKDAY.INTL(HC1,1,11) -> 45891 | HE1: =WORKDAY.INTL(HD1,1,11) -> 45892 | HF1: =WORKDAY.INTL(HE1,1,11) -> 45894 | HG1: =HF1+7-WEEKDAY(HF1-1)+1 -> 45901 | HH1: =HG1+7-WEEKDAY(HG1-1)+1 -> 45908 | HI1: =HH1+7-WEEKDAY(HH1-1)+1 -> 45915 | HJ1: =HI1+7-WEEKDAY(HI1-1)+1 -> 45922 | HK1: =HJ1+7-WEEKDAY(HJ1-1)+1 -> 45929 | HL1: =HK1+7-WEEKDAY(HK1-1)+1 -> 45936 | HM1: =HL1+7-WEEKDAY(HL1-1)+1 -> 45943 | HN1: =HM1+7-WEEKDAY(HM1-1)+1 -> 45950 | ... HT1: =HS1+7-WEEKDAY(HS1-1)+1 -> 45992 | HU1: Semanas de corto | HV1: Comentarios | HW1: Tipo
A2: 41CPAM01 | E2: 30 | GR2: AMBROTOSE AO CAPSULAS MANNATECH | GS2: 2 | GV2: =SUMIF(FACT_A1[cve_prod],DIM_BILL[[#This Row],[CODIGO]],FACT_A1[Existencia]) -> 0 | GW2: =SUMIF(FACT_A2[cve_prod],DIM_BILL[[#This Row],[CODIGO]],FACT_A2[Existencia]) -> 0 | GY2: Por Surtir & Parcial | GZ2: =SUMIFS(POs[saldo],POs[cve_prod],DIM_BILL[[#This Row],[CODIGO]],POs[status],$GY2,POs[f_ent],GZ$1) -> 0 | HA2: =SUMIFS(POs[saldo],POs[cve_prod],DIM_BILL[[#This Row],[CODIGO]],POs[status],$GY2,POs[f_ent],HA$1) -> 0 | HB2: =SUMIFS(POs[saldo],POs[cve_prod],DIM_BILL[[#This Row],[CODIGO]],POs[status],$GY2,POs[f_ent],HB$1) -> 0 | HC2: =SUMIFS(POs[saldo],POs[cve_prod],DIM_BILL[[#This Row],[CODIGO]],POs[status],$GY2,POs[f_ent],HC$1) -> 0 | HD2: =SUMIFS(POs[saldo],POs[cve_prod],DIM_BILL[[#This Row],[CODIGO]],POs[status],$GY2,POs[f_ent],HD$1) -> 0 | HE2: =SUMIFS(POs[saldo],POs[cve_prod],DIM_BILL[[#This Row],[CODIGO]],POs[status],$GY2,POs[f_ent],HE$1) -> 0 | HF2: =SUMIFS(POs[saldo],POs[cve_prod],DIM_BILL[[#This Row],[CODIGO]],POs[status],$GY2,POs[Semana],WEEKNUM(HF$1)) -> 0 | HG2: =SUMIFS(POs[saldo],POs[cve_prod],DIM_BILL[[#This Row],[CODIGO]],POs[status],$GY2,POs[Semana],WEEKNUM(HG$1)) -> 0 | HH2: =SUMIFS(POs[saldo],POs[cve_prod],DIM_BILL[[#This Row],[CODIGO]],POs[status],$GY2,POs[Semana],WEEKNUM(HH$1)) -> 0 | HI2: =SUMIFS(POs[saldo],POs[cve_prod],DIM_BILL[[#This Row],[CODIGO]],POs[status],$GY2,POs[Semana],WEEKNUM(HI$1)) -> 0 | HJ2: =SUMIFS(POs[saldo],POs[cve_prod],DIM_BILL[[#This Row],[CODIGO]],POs[status],$GY2,POs[Semana],WEEKNUM(HJ$1)) -> 0 | HK2: =SUMIFS(POs[saldo],POs[cve_prod],DIM_BILL[[#This Row],[CODIGO]],POs[status],$GY2,POs[Semana],WEEKNUM(HK$1)) -> 0 | HL2: =SUMIFS(POs[saldo],POs[cve_prod],DIM_BILL[[#This Row],[CODIGO]],POs[status],$GY2,POs[Semana],WEEKNUM(HL$1)) -> 0 | HM2: =SUMIFS(POs[saldo],POs[cve_prod],DIM_BILL[[#This Row],[CODIGO]],POs[status],$GY2,POs[Semana],WEEKNUM(HM$1)) -> 0 | ... HT2: =SUMIFS(POs[saldo],POs[cve_prod],DIM_BILL[[#This Row],[CODIGO]],POs[status],$GY2,POs[Semana],WEEKNUM(HT$1)) -> 0 | HW2: =DIM_BILL[[#This Row],[Tipo]]
A3: 41CPAM01 | E3: 30 | GR3: AMBROTOSE AO CAPSULAS MANNATECH | GS3: 2 | GV3: =SUMIF(FACT_A1[cve_prod],DIM_BILL[[#This Row],[CODIGO]],FACT_A1[Existencia]) -> 0 | GW3: =SUMIF(FACT_A2[cve_prod],DIM_BILL[[#This Row],[CODIGO]],FACT_A2[Existencia]) -> 0 | GY3: Demanda | GZ3: =SUMPRODUCT($B3:$GQ3,INDEX(PLAN_PRODUCCION!$B$4:$GQ$24,COLUMN()-COLUMN($GZ$1)+1,0)) -> 60000 | HA3: =SUMPRODUCT($B3:$GQ3,INDEX(PLAN_PRODUCCION!$B$4:$GQ$24,COLUMN()-COLUMN($GZ$1)+1,0)) -> 0 | HB3: =SUMPRODUCT($B3:$GQ3,INDEX(PLAN_PRODUCCION!$B$4:$GQ$24,COLUMN()-COLUMN($GZ$1)+1,0)) -> 0 | HC3: =SUMPRODUCT($B3:$GQ3,INDEX(PLAN_PRODUCCION!$B$4:$GQ$24,COLUMN()-COLUMN($GZ$1)+1,0)) -> 0 | HD3: =SUMPRODUCT($B3:$GQ3,INDEX(PLAN_PRODUCCION!$B$4:$GQ$24,COLUMN()-COLUMN($GZ$1)+1,0)) -> 0 | HE3: =SUMPRODUCT($B3:$GQ3,INDEX(PLAN_PRODUCCION!$B$4:$GQ$24,COLUMN()-COLUMN($GZ$1)+1,0)) -> 0 | HF3: =SUMPRODUCT($B3:$GQ3,INDEX(PLAN_PRODUCCION!$B$4:$GQ$24,COLUMN()-COLUMN($GZ$1)+1,0)) -> 0 | HG3: =SUMPRODUCT($B3:$GQ3,INDEX(PLAN_PRODUCCION!$B$4:$GQ$24,COLUMN()-COLUMN($GZ$1)+1,0)) -> 0 | ... HT3: =SUMPRODUCT($B3:$GQ3,INDEX(PLAN_PRODUCCION!$B$4:$GQ$24,COLUMN()-COLUMN($GZ$1)+1,0)) -> 0 | HW3: =DIM_BILL[[#This Row],[Tipo]]
A4: 41CPAM01 | E4: 30 | GR4: AMBROTOSE AO CAPSULAS MANNATECH | GS4: 2 | GV4: =SUMIF(FACT_A1[cve_prod],DIM_BILL[[#This Row],[CODIGO]],FACT_A1[Existencia]) -> 0 | GW4: =SUMIF(FACT_A2[cve_prod],DIM_BILL[[#This Row],[CODIGO]],FACT_A2[Existencia]) -> 0 | GY4: Cortos + PO's Confirmadas | GZ4: =GV4+GW4+GX4+GZ2-GZ3 -> -60000 | HA4: =GZ4+HA2-HA3 -> -60000 | HB4: =HA4+HB2-HB3 -> -60000 | HC4: =HB4+HC2-HC3 -> -60000 | HD4: =HC4+HD2-HD3 -> -60000 | HE4: =HD4+HE2-HE3 -> -60000 | HF4: =HE4+HF2-HF3 -> -60000 | HG4: =HF4+HG2-HG3 -> -60000 | HH4: =HG4+HH2-HH3 -> -60000 | ... HT4: =HS4+HT2-HT3 -> -60000 | HU4: =COUNTIF(GZ4:HT4,"<0") -> 21 | HW4: =DIM_BILL[[#This Row],[Tipo]]
A5: 41PRAB02 | BL5: 0.0013331765 | BM5: 4.4439216e-05 | GR5: PREMEZCLA COLAGENO PEPTAN P 5000 LD + D3 | GS5: 2 | GT5: Aspen Labs | GU5: MATERIA PRIMA | GV5: =SUMIF(FACT_A1[cve_prod],DIM_BILL[[#This Row],[CODIGO]],FACT_A1[Existencia]) -> 0 | GW5: =SUMIF(FACT_A2[cve_prod],DIM_BILL[[#This Row],[CODIGO]],FACT_A2[Existencia]) -> 37.731 | GY5: Por Surtir & Parcial | GZ5: =SUMIFS(POs[saldo],POs[cve_prod],DIM_BILL[[#This Row],[CODIGO]],POs[status],$GY5,POs[f_ent],GZ$1) -> 0 | HA5: =SUMIFS(POs[saldo],POs[cve_prod],DIM_BILL[[#This Row],[CODIGO]],POs[status],$GY5,POs[f_ent],HA$1) -> 0 | HB5: =SUMIFS(POs[saldo],POs[cve_prod],DIM_BILL[[#This Row],[CODIGO]],POs[status],$GY5,POs[f_ent],HB$1) -> 0 | HC5: =SUMIFS(POs[saldo],POs[cve_prod],DIM_BILL[[#This Row],[CODIGO]],POs[status],$GY5,POs[f_ent],HC$1) -> 0 | HD5: =SUMIFS(POs[saldo],POs[cve_prod],DIM_BILL[[#This Row],[CODIGO]],POs[status],$GY5,POs[f_ent],HD$1) -> 0 | HE5: =SUMIFS(POs[saldo],POs[cve_prod],DIM_BILL[[#This Row],[CODIGO]],POs[status],$GY5,POs[f_ent],HE$1) -> 0 | HF5: =SUMIFS(POs[saldo],POs[cve_prod],DIM_BILL[[#This Row],[CODIGO]],POs[status],$GY5,POs[Semana],WEEKNUM(HF$1)) -> 0 | HG5: =SUMIFS(POs[saldo],POs[cve_prod],DIM_BILL[[#This Row],[CODIGO]],POs[status],$GY5,POs[Semana],WEEKNUM(HG$1)) -> 0 | HH5: =SUMIFS(POs[saldo],POs[cve_prod],DIM_BILL[[#This Row],[CODIGO]],POs[status],$GY5,POs[Semana],WEEKNUM(HH$1)) -> 0 | HI5: =SUMIFS(POs[saldo],POs[cve_prod],DIM_BILL[[#This Row],[CODIGO]],POs[status],$GY5,POs[Semana],WEEKNUM(HI$1)) -> 0 | HJ5: =SUMIFS(POs[saldo],POs[cve_prod],DIM_BILL[[#This Row],[CODIGO]],POs[status],$GY5,POs[Semana],WEEKNUM(HJ$1)) -> 0 | HK5: =SUMIFS(POs[saldo],POs[cve_prod],DIM_BILL[[#This Row],[CODIGO]],POs[status],$GY5,POs[Semana],WEEKNUM(HK$1)) -> 0 | HL5: =SUMIFS(POs[saldo],POs[cve_prod],DIM_BILL[[#This Row],[CODIGO]],POs[status],$GY5,POs[Semana],WEEKNUM(HL$1)) -> 0 | HM5: =SUMIFS(POs[saldo],POs[cve_prod],DIM_BILL[[#This Row],[CODIGO]],POs[status],$GY5,POs[Semana],WEEKNUM(HM$1)) -> 0 | ... HT5: =SUMIFS(POs[saldo],POs[cve_prod],DIM_BILL[[#This Row],[CODIGO]],POs[status],$GY5,POs[Semana],WEEKNUM(HT$1)) -> 0 | HW5: =DIM_BILL[[#This Row],[Tipo]] -> MATERIA PRIMA
A6: 41PRAB02 | BL6: 0.0013331765 | BM6: 4.4439216e-05 | GR6: PREMEZCLA COLAGENO PEPTAN P 5000 LD + D3 | GS6: 2 | GT6: Aspen Labs | GU6: MATERIA PRIMA | GV6: =SUMIF(FACT_A1[cve_prod],DIM_BILL[[#This Row],[CODIGO]],FACT_A1[Existencia]) -> 0 | GW6: =SUMIF(FACT_A2[cve_prod],DIM_BILL[[#This Row],[CODIGO]],FACT_A2[Existencia]) -> 37.731 | GY6: Demanda | GZ6: =SUMPRODUCT($B6:$GQ6,INDEX(PLAN_PRODUCCION!$B$4:$GQ$24,COLUMN()-COLUMN($GZ$1)+1,0)) -> 7.683096 | HA6: =SUMPRODUCT($B6:$GQ6,INDEX(PLAN_PRODUCCION!$B$4:$GQ$24,COLUMN()-COLUMN($GZ$1)+1,0)) -> 0 | HB6: =SUMPRODUCT($B6:$GQ6,INDEX(PLAN_PRODUCCION!$B$4:$GQ$24,COLUMN()-COLUMN($GZ$1)+1,0)) -> 0 | HC6: =SUMPRODUCT($B6:$GQ6,INDEX(PLAN_PRODUCCION!$B$4:$GQ$24,COLUMN()-COLUMN($GZ$1)+1,0)) -> 0 | HD6: =SUMPRODUCT($B6:$GQ6,INDEX(PLAN_PRODUCCION!$B$4:$GQ$24,COLUMN()-COLUMN($GZ$1)+1,0)) -> 0 | HE6: =SUMPRODUCT($B6:$GQ6,INDEX(PLAN_PRODUCCION!$B$4:$GQ$24,COLUMN()-COLUMN($GZ$1)+1,0)) -> 0 | HF6: =SUMPRODUCT($B6:$GQ6,INDEX(PLAN_PRODUCCION!$B$4:$GQ$24,COLUMN()-COLUMN($GZ$1)+1,0)) -> 9.0656 | HG6: =SUMPRODUCT($B6:$GQ6,INDEX(PLAN_PRODUCCION!$B$4:$GQ$24,COLUMN()-COLUMN($GZ$1)+1,0)) -> 9.0656 | ... HT6: =SUMPRODUCT($B6:$GQ6,INDEX(PLAN_PRODUCCION!$B$4:$GQ$24,COLUMN()-COLUMN($GZ$1)+1,0)) -> 0 | HW6: =DIM_BILL[[#This Row],[Tipo]] -> MATERIA PRIMA
A7: 41PRAB02 | BL7: 0.0013331765 | BM7: 4.4439216e-05 | GR7: PREMEZCLA COLAGENO PEPTAN P 5000 LD + D3 | GS7: 2 | GT7: Aspen Labs | GU7: MATERIA PRIMA | GV7: =SUMIF(FACT_A1[cve_prod],DIM_BILL[[#This Row],[CODIGO]],FACT_A1[Existencia]) -> 0 | GW7: =SUMIF(FACT_A2[cve_prod],DIM_BILL[[#This Row],[CODIGO]],FACT_A2[Existencia]) -> 37.731 | GY7: Cortos + PO's Confirmadas | GZ7: =GV7+GW7+GX7+GZ5-GZ6 -> 30.047904 | HA7: =GZ7+HA5-HA6 -> 30.047904 | HB7: =HA7+HB5-HB6 -> 30.047904 | HC7: =HB7+HC5-HC6 -> 30.047904 | HD7: =HC7+HD5-HD6 -> 30.047904 | HE7: =HD7+HE5-HE6 -> 30.047904 | HF7: =HE7+HF5-HF6 -> 20.982304 | HG7: =HF7+HG5-HG6 -> 11.916704 | HH7: =HG7+HH5-HH6 -> 11.916704 | ... HT7: =HS7+HT5-HT6 -> 11.916704 | HU7: =COUNTIF(GZ7:HT7,"<0") -> 0 | HW7: =DIM_BILL[[#This Row],[Tipo]] -> MATERIA PRIMA
A8: 51PLHG17 | DX8: 10 | GR8: HIDRA2GO UVA SOBRES 6g ST | GS8: 2 | GV8: =SUMIF(FACT_A1[cve_prod],DIM_BILL[[#This Row],[CODIGO]],FACT_A1[Existencia]) -> 0 | GY8: Por Surtir & Parcial | GZ8: =SUMIFS(POs[saldo],POs[cve_prod],DIM_BILL[[#This Row],[CODIGO]],POs[status],$GY8,POs[f_ent],GZ$1) -> 0 | HA8: =SUMIFS(POs[saldo],POs[cve_prod],DIM_BILL[[#This Row],[CODIGO]],POs[status],$GY8,POs[f_ent],HA$1) -> 0 | HB8: =SUMIFS(POs[saldo],POs[cve_prod],DIM_BILL[[#This Row],[CODIGO]],POs[status],$GY8,POs[f_ent],HB$1) -> 0 | HC8: =SUMIFS(POs[saldo],POs[cve_prod],DIM_BILL[[#This Row],[CODIGO]],POs[status],$GY8,POs[f_ent],HC$1) -> 0 | HD8: =SUMIFS(POs[saldo],POs[cve_prod],DIM_BILL[[#This Row],[CODIGO]],POs[status],$GY8,POs[f_ent],HD$1) -> 0 | HE8: =SUMIFS(POs[saldo],POs[cve_prod],DIM_BILL[[#This Row],[CODIGO]],POs[status],$GY8,POs[f_ent],HE$1) -> 0 | HF8: =SUMIFS(POs[saldo],POs[cve_prod],DIM_BILL[[#This Row],[CODIGO]],POs[status],$GY8,POs[Semana],WEEKNUM(HF$1)) -> 0 | HG8: =SUMIFS(POs[saldo],POs[cve_prod],DIM_BILL[[#This Row],[CODIGO]],POs[status],$GY8,POs[Semana],WEEKNUM(HG$1)) -> 0 | HH8: =SUMIFS(POs[saldo],POs[cve_prod],DIM_BILL[[#This Row],[CODIGO]],POs[status],$GY8,POs[Semana],WEEKNUM(HH$1)) -> 0 | HI8: =SUMIFS(POs[saldo],POs[cve_prod],DIM_BILL[[#This Row],[CODIGO]],POs[status],$GY8,POs[Semana],WEEKNUM(HI$1)) -> 0 | HJ8: =SUMIFS(POs[saldo],POs[cve_prod],DIM_BILL[[#This Row],[CODIGO]],POs[status],$GY8,POs[Semana],WEEKNUM(HJ$1)) -> 0 | HK8: =SUMIFS(POs[saldo],POs[cve_prod],DIM_BILL[[#This Row],[CODIGO]],POs[status],$GY8,POs[Semana],WEEKNUM(HK$1)) -> 0 | HL8: =SUMIFS(POs[saldo],POs[cve_prod],DIM_BILL[[#This Row],[CODIGO]],POs[status],$GY8,POs[Semana],WEEKNUM(HL$1)) -> 0 | HM8: =SUMIFS(POs[saldo],POs[cve_prod],DIM_BILL[[#This Row],[CODIGO]],POs[status],$GY8,POs[Semana],WEEKNUM(HM$1)) -> 0 | ... HT8: =SUMIFS(POs[saldo],POs[cve_prod],DIM_BILL[[#This Row],[CODIGO]],POs[status],$GY8,POs[Semana],WEEKNUM(HT$1)) -> 0 | HW8: =DIM_BILL[[#This Row],[Tipo]]
A9: 51PLHG17 | DX9: 10 | GR9: HIDRA2GO UVA SOBRES 6g ST | GS9: 2 | GV9: =SUMIF(FACT_A1[cve_prod],DIM_BILL[[#This Row],[CODIGO]],FACT_A1[Existencia]) -> 0 | GW9: =SUMIF(FACT_A2[cve_prod],DIM_BILL[[#This Row],[CODIGO]],FACT_A2[Existencia]) -> 0 | GY9: Demanda | GZ9: =SUMPRODUCT($B9:$GQ9,INDEX(PLAN_PRODUCCION!$B$4:$GQ$24,COLUMN()-COLUMN($GZ$1)+1,0)) -> 0 | HA9: =SUMPRODUCT($B9:$GQ9,INDEX(PLAN_PRODUCCION!$B$4:$GQ$24,COLUMN()-COLUMN($GZ$1)+1,0)) -> 0 | HB9: =SUMPRODUCT($B9:$GQ9,INDEX(PLAN_PRODUCCION!$B$4:$GQ$24,COLUMN()-COLUMN($GZ$1)+1,0)) -> 0 | HC9: =SUMPRODUCT($B9:$GQ9,INDEX(PLAN_PRODUCCION!$B$4:$GQ$24,COLUMN()-COLUMN($GZ$1)+1,0)) -> 0 | HD9: =SUMPRODUCT($B9:$GQ9,INDEX(PLAN_PRODUCCION!$B$4:$GQ$24,COLUMN()-COLUMN($GZ$1)+1,0)) -> 0 | HE9: =SUMPRODUCT($B9:$GQ9,INDEX(PLAN_PRODUCCION!$B$4:$GQ$24,COLUMN()-COLUMN($GZ$1)+1,0)) -> 0 | HF9: =SUMPRODUCT($B9:$GQ9,INDEX(PLAN_PRODUCCION!$B$4:$GQ$24,COLUMN()-COLUMN($GZ$1)+1,0)) -> 0 | HG9: =SUMPRODUCT($B9:$GQ9,INDEX(PLAN_PRODUCCION!$B$4:$GQ$24,COLUMN()-COLUMN($GZ$1)+1,0)) -> 0 | ... HT9: =SUMPRODUCT($B9:$GQ9,INDEX(PLAN_PRODUCCION!$B$4:$GQ$24,COLUMN()-COLUMN($GZ$1)+1,0)) -> 0 | HW9: =DIM_BILL[[#This Row],[Tipo]]
A10: 51PLHG17 | DX10: 10 | GR10: HIDRA2GO UVA SOBRES 6g ST | GS10: 2 | GV10: =SUMIF(FACT_A1[cve_prod],DIM_BILL[[#This Row],[CODIGO]],FACT_A1[Existencia]) -> 0 | GW10: =SUMIF(FACT_A2[cve_prod],DIM_BILL[[#This Row],[CODIGO]],FACT_A2[Existencia]) -> 0 | GY10: Cortos + PO's Confirmadas | GZ10: =GV10+GW10+GX10+GZ8-GZ9 -> 0 | HA10: =GZ10+HA8-HA9 -> 0 | HB10: =HA10+HB8-HB9 -> 0 | HC10: =HB10+HC8-HC9 -> 0 | HD10: =HC10+HD8-HD9 -> 0 | HE10: =HD10+HE8-HE9 -> 0 | HF10: =HE10+HF8-HF9 -> 0 | HG10: =HF10+HG8-HG9 -> 0 | HH10: =HG10+HH8-HH9 -> 0 | ... HT10: =HS10+HT8-HT9 -> 0 | HU10: =COUNTIF(GZ10:HT10,"<0") -> 0 | HW10: =DIM_BILL[[#This Row],[Tipo]]
A11: 51PLHG19 | DY11: 25.75 | GR11: HIDRA2GO MORA AZUL SOBRES 6g ST | GS11: 2 | GV11: =SUMIF(FACT_A1[cve_prod],DIM_BILL[[#This Row],[CODIGO]],FACT_A1[Existencia]) -> 0 | GW11: =SUMIF(FACT_A2[cve_prod],DIM_BILL[[#This Row],[CODIGO]],FACT_A2[Existencia]) -> 0 | GY11: Por Surtir & Parcial | GZ11: =SUMIFS(POs[saldo],POs[cve_prod],DIM_BILL[[#This Row],[CODIGO]],POs[status],$GY11,POs[f_ent],GZ$1) -> 0 | HA11: =SUMIFS(POs[saldo],POs[cve_prod],DIM_BILL[[#This Row],[CODIGO]],POs[status],$GY11,POs[f_ent],HA$1) -> 0 | HB11: =SUMIFS(POs[saldo],POs[cve_prod],DIM_BILL[[#This Row],[CODIGO]],POs[status],$GY11,POs[f_ent],HB$1) -> 0 | HC11: =SUMIFS(POs[saldo],POs[cve_prod],DIM_BILL[[#This Row],[CODIGO]],POs[status],$GY11,POs[f_ent],HC$1) -> 0 | HD11: =SUMIFS(POs[saldo],POs[cve_prod],DIM_BILL[[#This Row],[CODIGO]],POs[status],$GY11,POs[f_ent],HD$1) -> 0 | HE11: =SUMIFS(POs[saldo],POs[cve_prod],DIM_BILL[[#This Row],[CODIGO]],POs[status],$GY11,POs[f_ent],HE$1) -> 0 | HF11: =SUMIFS(POs[saldo],POs[cve_prod],DIM_BILL[[#This Row],[CODIGO]],POs[status],$GY11,POs[Semana],WEEKNUM(HF$1)) -> 0 | HG11: =SUMIFS(POs[saldo],POs[cve_prod],DIM_BILL[[#This Row],[CODIGO]],POs[status],$GY11,POs[Semana],WEEKNUM(HG$1)) -> 0 | HH11: =SUMIFS(POs[saldo],POs[cve_prod],DIM_BILL[[#This Row],[CODIGO]],POs[status],$GY11,POs[Semana],WEEKNUM(HH$1)) -> 0 | HI11: =SUMIFS(POs[saldo],POs[cve_prod],DIM_BILL[[#This Row],[CODIGO]],POs[status],$GY11,POs[Semana],WEEKNUM(HI$1)) -> 0 | HJ11: =SUMIFS(POs[saldo],POs[cve_prod],DIM_BILL[[#This Row],[CODIGO]],POs[status],$GY11,POs[Semana],WEEKNUM(HJ$1)) -> 0 | HK11: =SUMIFS(POs[saldo],POs[cve_prod],DIM_BILL[[#This Row],[CODIGO]],POs[status],$GY11,POs[Semana],WEEKNUM(HK$1)) -> 0 | HL11: =SUMIFS(POs[saldo],POs[cve_prod],DIM_BILL[[#This Row],[CODIGO]],POs[status],$GY11,POs[Semana],WEEKNUM(HL$1)) -> 0 | HM11: =SUMIFS(POs[saldo],POs[cve_prod],DIM_BILL[[#This Row],[CODIGO]],POs[status],$GY11,POs[Semana],WEEKNUM(HM$1)) -> 0 | ... HT11: =SUMIFS(POs[saldo],POs[cve_prod],DIM_BILL[[#This Row],[CODIGO]],POs[status],$GY11,POs[Semana],WEEKNUM(HT$1)) -> 0 | HW11: =DIM_BILL[[#This Row],[Tipo]]
A12: 51PLHG19 | DY12: 25.75 | GR12: HIDRA2GO MORA AZUL SOBRES 6g ST | GS12: 2 | GV12: =SUMIF(FACT_A1[cve_prod],DIM_BILL[[#This Row],[CODIGO]],FACT_A1[Existencia]) -> 0 | GW12: =SUMIF(FACT_A2[cve_prod],DIM_BILL[[#This Row],[CODIGO]],FACT_A2[Existencia]) -> 0 | GY12: Demanda | GZ12: =SUMPRODUCT($B12:$GQ12,INDEX(PLAN_PRODUCCION!$B$4:$GQ$24,COLUMN()-COLUMN($GZ$1)+1,0)) -> 92700 | HA12: =SUMPRODUCT($B12:$GQ12,INDEX(PLAN_PRODUCCION!$B$4:$GQ$24,COLUMN()-COLUMN($GZ$1)+1,0)) -> 0 | HB12: =SUMPRODUCT($B12:$GQ12,INDEX(PLAN_PRODUCCION!$B$4:$GQ$24,COLUMN()-COLUMN($GZ$1)+1,0)) -> 0 | HC12: =SUMPRODUCT($B12:$GQ12,INDEX(PLAN_PRODUCCION!$B$4:$GQ$24,COLUMN()-COLUMN($GZ$1)+1,0)) -> 0 | HD12: =SUMPRODUCT($B12:$GQ12,INDEX(PLAN_PRODUCCION!$B$4:$GQ$24,COLUMN()-COLUMN($GZ$1)+1,0)) -> 0 | HE12: =SUMPRODUCT($B12:$GQ12,INDEX(PLAN_PRODUCCION!$B$4:$GQ$24,COLUMN()-COLUMN($GZ$1)+1,0)) -> 0 | HF12: =SUMPRODUCT($B12:$GQ12,INDEX(PLAN_PRODUCCION!$B$4:$GQ$24,COLUMN()-COLUMN($GZ$1)+1,0)) -> 0 | HG12: =SUMPRODUCT($B12:$GQ12,INDEX(PLAN_PRODUCCION!$B$4:$GQ$24,COLUMN()-COLUMN($GZ$1)+1,0)) -> 0 | ... HT12: =SUMPRODUCT($B12:$GQ12,INDEX(PLAN_PRODUCCION!$B$4:$GQ$24,COLUMN()-COLUMN($GZ$1)+1,0)) -> 0 | HW12: =DIM_BILL[[#This Row],[Tipo]]
A13: 51PLHG19 | DY13: 25.75 | GR13: HIDRA2GO MORA AZUL SOBRES 6g ST | GS13: 2 | GV13: =SUMIF(FACT_A1[cve_prod],DIM_BILL[[#This Row],[CODIGO]],FACT_A1[Existencia]) -> 0 | GW13: =SUMIF(FACT_A2[cve_prod],DIM_BILL[[#This Row],[CODIGO]],FACT_A2[Existencia]) -> 0 | GY13: Cortos + PO's Confirmadas | GZ13: =GV13+GW13+GX13+GZ11-GZ12 -> -92700 | HA13: =GZ13+HA11-HA12 -> -92700 | HB13: =HA13+HB11-HB12 -> -92700 | HC13: =HB13+HC11-HC12 -> -92700 | HD13: =HC13+HD11-HD12 -> -92700 | HE13: =HD13+HE11-HE12 -> -92700 | HF13: =HE13+HF11-HF12 -> -92700 | HG13: =HF13+HG11-HG12 -> -92700 | HH13: =HG13+HH11-HH12 -> -92700 | ... HT13: =HS13+HT11-HT12 -> -92700 | HU13: =COUNTIF(GZ13:HT13,"<0") -> 21 | HW13: =DIM_BILL[[#This Row],[Tipo]]
A14: 51PLHG22 | EA14: 10 | GR14: HIDRA2GO FRESA-KIWI SOBRES 6g ST | GS14: 2 | GV14: =SUMIF(FACT_A1[cve_prod],DIM_BILL[[#This Row],[CODIGO]],FACT_A1[Existencia]) -> 0 | GW14: =SUMIF(FACT_A2[cve_prod],DIM_BILL[[#This Row],[CODIGO]],FACT_A2[Existencia]) -> 0 | GY14: Por Surtir & Parcial | GZ14: =SUMIFS(POs[saldo],POs[cve_prod],DIM_BILL[[#This Row],[CODIGO]],POs[status],$GY14,POs[f_ent],GZ$1) -> 0 | HA14: =SUMIFS(POs[saldo],POs[cve_prod],DIM_BILL[[#This Row],[CODIGO]],POs[status],$GY14,POs[f_ent],HA$1) -> 0 | HB14: =SUMIFS(POs[saldo],POs[cve_prod],DIM_BILL[[#This Row],[CODIGO]],POs[status],$GY14,POs[f_ent],HB$1) -> 0 | HC14: =SUMIFS(POs[saldo],POs[cve_prod],DIM_BILL[[#This Row],[CODIGO]],POs[status],$GY14,POs[f_ent],HC$1) -> 0 | HD14: =SUMIFS(POs[saldo],POs[cve_prod],DIM_BILL[[#This Row],[CODIGO]],POs[status],$GY14,POs[f_ent],HD$1) -> 0 | HE14: =SUMIFS(POs[saldo],POs[cve_prod],DIM_BILL[[#This Row],[CODIGO]],POs[status],$GY14,POs[f_ent],HE$1) -> 0 | HF14: =SUMIFS(POs[saldo],POs[cve_prod],DIM_BILL[[#This Row],[CODIGO]],POs[status],$GY14,POs[Semana],WEEKNUM(HF$1)) -> 0 | HG14: =SUMIFS(POs[saldo],POs[cve_prod],DIM_BILL[[#This Row],[CODIGO]],POs[status],$GY14,POs[Semana],WEEKNUM(HG$1)) -> 0 | HH14: =SUMIFS(POs[saldo],POs[cve_prod],DIM_BILL[[#This Row],[CODIGO]],POs[status],$GY14,POs[Semana],WEEKNUM(HH$1)) -> 0 | HI14: =SUMIFS(POs[saldo],POs[cve_prod],DIM_BILL[[#This Row],[CODIGO]],POs[status],$GY14,POs[Semana],WEEKNUM(HI$1)) -> 0 | HJ14: =SUMIFS(POs[saldo],POs[cve_prod],DIM_BILL[[#This Row],[CODIGO]],POs[status],$GY14,POs[Semana],WEEKNUM(HJ$1)) -> 0 | HK14: =SUMIFS(POs[saldo],POs[cve_prod],DIM_BILL[[#This Row],[CODIGO]],POs[status],$GY14,POs[Semana],WEEKNUM(HK$1)) -> 0 | HL14: =SUMIFS(POs[saldo],POs[cve_prod],DIM_BILL[[#This Row],[CODIGO]],POs[status],$GY14,POs[Semana],WEEKNUM(HL$1)) -> 0 | HM14: =SUMIFS(POs[saldo],POs[cve_prod],DIM_BILL[[#This Row],[CODIGO]],POs[status],$GY14,POs[Semana],WEEKNUM(HM$1)) -> 0 | ... HT14: =SUMIFS(POs[saldo],POs[cve_prod],DIM_BILL[[#This Row],[CODIGO]],POs[status],$GY14,POs[Semana],WEEKNUM(HT$1)) -> 0 | HW14: =DIM_BILL[[#This Row],[Tipo]]
A15: 51PLHG22 | EA15: 10 | GR15: HIDRA2GO FRESA-KIWI SOBRES 6g ST | GS15: 2 | GV15: =SUMIF(FACT_A1[cve_prod],DIM_BILL[[#This Row],[CODIGO]],FACT_A1[Existencia]) -> 0 | GW15: =SUMIF(FACT_A2[cve_prod],DIM_BILL[[#This Row],[CODIGO]],FACT_A2[Existencia]) -> 0 | GY15: Demanda | GZ15: =SUMPRODUCT($B15:$GQ15,INDEX(PLAN_PRODUCCION!$B$4:$GQ$24,COLUMN()-COLUMN($GZ$1)+1,0)) -> 0 | HA15: =SUMPRODUCT($B15:$GQ15,INDEX(PLAN_PRODUCCION!$B$4:$GQ$24,COLUMN()-COLUMN($GZ$1)+1,0)) -> 0 | HB15: =SUMPRODUCT($B15:$GQ15,INDEX(PLAN_PRODUCCION!$B$4:$GQ$24,COLUMN()-COLUMN($GZ$1)+1,0)) -> 0 | HC15: =SUMPRODUCT($B15:$GQ15,INDEX(PLAN_PRODUCCION!$B$4:$GQ$24,COLUMN()-COLUMN($GZ$1)+1,0)) -> 0 | HD15: =SUMPRODUCT($B15:$GQ15,INDEX(PLAN_PRODUCCION!$B$4:$GQ$24,COLUMN()-COLUMN($GZ$1)+1,0)) -> 0 | HE15: =SUMPRODUCT($B15:$GQ15,INDEX(PLAN_PRODUCCION!$B$4:$GQ$24,COLUMN()-COLUMN($GZ$1)+1,0)) -> 0 | HF15: =SUMPRODUCT($B15:$GQ15,INDEX(PLAN_PRODUCCION!$B$4:$GQ$24,COLUMN()-COLUMN($GZ$1)+1,0)) -> 0 | HG15: =SUMPRODUCT($B15:$GQ15,INDEX(PLAN_PRODUCCION!$B$4:$GQ$24,COLUMN()-COLUMN($GZ$1)+1,0)) -> 0 | ... HT15: =SUMPRODUCT($B15:$GQ15,INDEX(PLAN_PRODUCCION!$B$4:$GQ$24,COLUMN()-COLUMN($GZ$1)+1,0)) -> 0 | HW15: =DIM_BILL[[#This Row],[Tipo]]
A16: 51PLHG22 | EA16: 10 | GR16: HIDRA2GO FRESA-KIWI SOBRES 6g ST | GS16: 2 | GV16: =SUMIF(FACT_A1[cve_prod],DIM_BILL[[#This Row],[CODIGO]],FACT_A1[Existencia]) -> 0 | GW16: =SUMIF(FACT_A2[cve_prod],DIM_BILL[[#This Row],[CODIGO]],FACT_A2[Existencia]) -> 0 | GY16: Cortos + PO's Confirmadas | GZ16: =GV16+GW16+GX16+GZ14-GZ15 -> 0 | HA16: =GZ16+HA14-HA15 -> 0 | HB16: =HA16+HB14-HB15 -> 0 | HC16: =HB16+HC14-HC15 -> 0 | HD16: =HC16+HD14-HD15 -> 0 | HE16: =HD16+HE14-HE15 -> 0 | HF16: =HE16+HF14-HF15 -> 0 | HG16: =HF16+HG14-HG15 -> 0 | HH16: =HG16+HH14-HH15 -> 0 | ... HT16: =HS16+HT14-HT15 -> 0 | HU16: =COUNTIF(GZ16:HT16,"<0") -> 0 | HW16: =DIM_BILL[[#This Row],[Tipo]]
A17: 51TBMC02 | GC17: 1 | GR17: MULTILYTE COCO C/20 TABS EFER MIX ST | GS17: 2 | GV17: =SUMIF(FACT_A1[cve_prod],DIM_BILL[[#This Row],[CODIGO]],FACT_A1[Existencia]) -> 0 | GW17: =SUMIF(FACT_A2[cve_prod],DIM_BILL[[#This Row],[CODIGO]],FACT_A2[Existencia]) -> 0 | GY17: Por Surtir & Parcial | GZ17: =SUMIFS(POs[saldo],POs[cve_prod],DIM_BILL[[#This Row],[CODIGO]],POs[status],$GY17,POs[f_ent],GZ$1) -> 0 | HA17: =SUMIFS(POs[saldo],POs[cve_prod],DIM_BILL[[#This Row],[CODIGO]],POs[status],$GY17,POs[f_ent],HA$1) -> 0 | HB17: =SUMIFS(POs[saldo],POs[cve_prod],DIM_BILL[[#This Row],[CODIGO]],POs[status],$GY17,POs[f_ent],HB$1) -> 0 | HC17: =SUMIFS(POs[saldo],POs[cve_prod],DIM_BILL[[#This Row],[CODIGO]],POs[status],$GY17,POs[f_ent],HC$1) -> 0 | HD17: =SUMIFS(POs[saldo],POs[cve_prod],DIM_BILL[[#This Row],[CODIGO]],POs[status],$GY17,POs[f_ent],HD$1) -> 0 | HE17: =SUMIFS(POs[saldo],POs[cve_prod],DIM_BILL[[#This Row],[CODIGO]],POs[status],$GY17,POs[f_ent],HE$1) -> 0 | HF17: =SUMIFS(POs[saldo],POs[cve_prod],DIM_BILL[[#This Row],[CODIGO]],POs[status],$GY17,POs[Semana],WEEKNUM(HF$1)) -> 0 | HG17: =SUMIFS(POs[saldo],POs[cve_prod],DIM_BILL[[#This Row],[CODIGO]],POs[status],$GY17,POs[Semana],WEEKNUM(HG$1)) -> 0 | HH17: =SUMIFS(POs[saldo],POs[cve_prod],DIM_BILL[[#This Row],[CODIGO]],POs[status],$GY17,POs[Semana],WEEKNUM(HH$1)) -> 0 | HI17: =SUMIFS(POs[saldo],POs[cve_prod],DIM_BILL[[#This Row],[CODIGO]],POs[status],$GY17,POs[Semana],WEEKNUM(HI$1)) -> 0 | HJ17: =SUMIFS(POs[saldo],POs[cve_prod],DIM_BILL[[#This Row],[CODIGO]],POs[status],$GY17,POs[Semana],WEEKNUM(HJ$1)) -> 0 | HK17: =SUMIFS(POs[saldo],POs[cve_prod],DIM_BILL[[#This Row],[CODIGO]],POs[status],$GY17,POs[Semana],WEEKNUM(HK$1)) -> 0 | HL17: =SUMIFS(POs[saldo],POs[cve_prod],DIM_BILL[[#This Row],[CODIGO]],POs[status],$GY17,POs[Semana],WEEKNUM(HL$1)) -> 0 | HM17: =SUMIFS(POs[saldo],POs[cve_prod],DIM_BILL[[#This Row],[CODIGO]],POs[status],$GY17,POs[Semana],WEEKNUM(HM$1)) -> 0 | ... HT17: =SUMIFS(POs[saldo],POs[cve_prod],DIM_BILL[[#This Row],[CODIGO]],POs[status],$GY17,POs[Semana],WEEKNUM(HT$1)) -> 0 | HW17: =DIM_BILL[[#This Row],[Tipo]]
A18: 51TBMC02 | GC18: 1 | GR18: MULTILYTE COCO C/20 TABS EFER MIX ST | GS18: 2 | GV18: =SUMIF(FACT_A1[cve_prod],DIM_BILL[[#This Row],[CODIGO]],FACT_A1[Existencia]) -> 0 | GW18: =SUMIF(FACT_A2[cve_prod],DIM_BILL[[#This Row],[CODIGO]],FACT_A2[Existencia]) -> 0 | GY18: Demanda | GZ18: =SUMPRODUCT($B18:$GQ18,INDEX(PLAN_PRODUCCION!$B$4:$GQ$24,COLUMN()-COLUMN($GZ$1)+1,0)) -> 7000 | HA18: =SUMPRODUCT($B18:$GQ18,INDEX(PLAN_PRODUCCION!$B$4:$GQ$24,COLUMN()-COLUMN($GZ$1)+1,0)) -> 0 | HB18: =SUMPRODUCT($B18:$GQ18,INDEX(PLAN_PRODUCCION!$B$4:$GQ$24,COLUMN()-COLUMN($GZ$1)+1,0)) -> 0 | HC18: =SUMPRODUCT($B18:$GQ18,INDEX(PLAN_PRODUCCION!$B$4:$GQ$24,COLUMN()-COLUMN($GZ$1)+1,0)) -> 0 | HD18: =SUMPRODUCT($B18:$GQ18,INDEX(PLAN_PRODUCCION!$B$4:$GQ$24,COLUMN()-COLUMN($GZ$1)+1,0)) -> 0 | HE18: =SUMPRODUCT($B18:$GQ18,INDEX(PLAN_PRODUCCION!$B$4:$GQ$24,COLUMN()-COLUMN($GZ$1)+1,0)) -> 0 | HF18: =SUMPRODUCT($B18:$GQ18,INDEX(PLAN_PRODUCCION!$B$4:$GQ$24,COLUMN()-COLUMN($GZ$1)+1,0)) -> 0 | HG18: =SUMPRODUCT($B18:$GQ18,INDEX(PLAN_PRODUCCION!$B$4:$GQ$24,COLUMN()-COLUMN($GZ$1)+1,0)) -> 0 | ... HT18: =SUMPRODUCT($B18:$GQ18,INDEX(PLAN_PRODUCCION!$B$4:$GQ$24,COLUMN()-COLUMN($GZ$1)+1,0)) -> 0 | HW18: =DIM_BILL[[#This Row],[Tipo]]
A19: 51TBMC02 | GC19: 1 | GR19: MULTILYTE COCO C/20 TABS EFER MIX ST | GS19: 2 | GV19: =SUMIF(FACT_A1[cve_prod],DIM_BILL[[#This Row],[CODIGO]],FACT_A1[Existencia]) -> 0 | GW19: =SUMIF(FACT_A2[cve_prod],DIM_BILL[[#This Row],[CODIGO]],FACT_A2[Existencia]) -> 0 | GY19: Cortos + PO's Confirmadas | GZ19: =GV19+GW19+GX19+GZ17-GZ18 -> -7000 | HA19: =GZ19+HA17-HA18 -> -7000 | HB19: =HA19+HB17-HB18 -> -7000 | HC19: =HB19+HC17-HC18 -> -7000 | HD19: =HC19+HD17-HD18 -> -7000 | HE19: =HD19+HE17-HE18 -> -7000 | HF19: =HE19+HF17-HF18 -> -7000 | HG19: =HF19+HG17-HG18 -> -7000 | HH19: =HG19+HH17-HH18 -> -7000 | ... HT19: =HS19+HT17-HT18 -> -7000 | HU19: =COUNTIF(GZ19:HT19,"<0") -> 21 | HW19: =DIM_BILL[[#This Row],[Tipo]]
A20: 51TBMF02 | GC20: 1 | GR20: MULTILYTE FRESA KIWI 20 TABS EFER MIX ST | GS20: 2 | GV20: =SUMIF(FACT_A1[cve_prod],DIM_BILL[[#This Row],[CODIGO]],FACT_A1[Existencia]) -> 0 | GW20: =SUMIF(FACT_A2[cve_prod],DIM_BILL[[#This Row],[CODIGO]],FACT_A2[Existencia]) -> 0 | GY20: Por Surtir & Parcial | GZ20: =SUMIFS(POs[saldo],POs[cve_prod],DIM_BILL[[#This Row],[CODIGO]],POs[status],$GY20,POs[f_ent],GZ$1) -> 0 | HA20: =SUMIFS(POs[saldo],POs[cve_prod],DIM_BILL[[#This Row],[CODIGO]],POs[status],$GY20,POs[f_ent],HA$1) -> 0 | HB20: =SUMIFS(POs[saldo],POs[cve_prod],DIM_BILL[[#This Row],[CODIGO]],POs[status],$GY20,POs[f_ent],HB$1) -> 0 | HC20: =SUMIFS(POs[saldo],POs[cve_prod],DIM_BILL[[#This Row],[CODIGO]],POs[status],$GY20,POs[f_ent],HC$1) -> 0 | HD20: =SUMIFS(POs[saldo],POs[cve_prod],DIM_BILL[[#This Row],[CODIGO]],POs[status],$GY20,POs[f_ent],HD$1) -> 0 | HE20: =SUMIFS(POs[saldo],POs[cve_prod],DIM_BILL[[#This Row],[CODIGO]],POs[status],$GY20,POs[f_ent],HE$1) -> 0 | HF20: =SUMIFS(POs[saldo],POs[cve_prod],DIM_BILL[[#This Row],[CODIGO]],POs[status],$GY20,POs[Semana],WEEKNUM(HF$1)) -> 0 | HG20: =SUMIFS(POs[saldo],POs[cve_prod],DIM_BILL[[#This Row],[CODIGO]],POs[status],$GY20,POs[Semana],WEEKNUM(HG$1)) -> 0 | HH20: =SUMIFS(POs[saldo],POs[cve_prod],DIM_BILL[[#This Row],[CODIGO]],POs[status],$GY20,POs[Semana],WEEKNUM(HH$1)) -> 0 | HI20: =SUMIFS(POs[saldo],POs[cve_prod],DIM_BILL[[#This Row],[CODIGO]],POs[status],$GY20,POs[Semana],WEEKNUM(HI$1)) -> 0 | HJ20: =SUMIFS(POs[saldo],POs[cve_prod],DIM_BILL[[#This Row],[CODIGO]],POs[status],$GY20,POs[Semana],WEEKNUM(HJ$1)) -> 0 | HK20: =SUMIFS(POs[saldo],POs[cve_prod],DIM_BILL[[#This Row],[CODIGO]],POs[status],$GY20,POs[Semana],WEEKNUM(HK$1)) -> 0 | HL20: =SUMIFS(POs[saldo],POs[cve_prod],DIM_BILL[[#This Row],[CODIGO]],POs[status],$GY20,POs[Semana],WEEKNUM(HL$1)) -> 0 | HM20: =SUMIFS(POs[saldo],POs[cve_prod],DIM_BILL[[#This Row],[CODIGO]],POs[status],$GY20,POs[Semana],WEEKNUM(HM$1)) -> 0 | ... HT20: =SUMIFS(POs[saldo],POs[cve_prod],DIM_BILL[[#This Row],[CODIGO]],POs[status],$GY20,POs[Semana],WEEKNUM(HT$1)) -> 0 | HW20: =DIM_BILL[[#This Row],[Tipo]]
A21: 51TBMF02 | GC21: 1 | GR21: MULTILYTE FRESA KIWI 20 TABS EFER MIX ST | GS21: 2 | GV21: =SUMIF(FACT_A1[cve_prod],DIM_BILL[[#This Row],[CODIGO]],FACT_A1[Existencia]) -> 0 | GW21: =SUMIF(FACT_A2[cve_prod],DIM_BILL[[#This Row],[CODIGO]],FACT_A2[Existencia]) -> 0 | GY21: Demanda | GZ21: =SUMPRODUCT($B21:$GQ21,INDEX(PLAN_PRODUCCION!$B$4:$GQ$24,COLUMN()-COLUMN($GZ$1)+1,0)) -> 7000 | HA21: =SUMPRODUCT($B21:$GQ21,INDEX(PLAN_PRODUCCION!$B$4:$GQ$24,COLUMN()-COLUMN($GZ$1)+1,0)) -> 0 | HB21: =SUMPRODUCT($B21:$GQ21,INDEX(PLAN_PRODUCCION!$B$4:$GQ$24,COLUMN()-COLUMN($GZ$1)+1,0)) -> 0 | HC21: =SUMPRODUCT($B21:$GQ21,INDEX(PLAN_PRODUCCION!$B$4:$GQ$24,COLUMN()-COLUMN($GZ$1)+1,0)) -> 0 | HD21: =SUMPRODUCT($B21:$GQ21,INDEX(PLAN_PRODUCCION!$B$4:$GQ$24,COLUMN()-COLUMN($GZ$1)+1,0)) -> 0 | HE21: =SUMPRODUCT($B21:$GQ21,INDEX(PLAN_PRODUCCION!$B$4:$GQ$24,COLUMN()-COLUMN($GZ$1)+1,0)) -> 0 | HF21: =SUMPRODUCT($B21:$GQ21,INDEX(PLAN_PRODUCCION!$B$4:$GQ$24,COLUMN()-COLUMN($GZ$1)+1,0)) -> 0 | HG21: =SUMPRODUCT($B21:$GQ21,INDEX(PLAN_PRODUCCION!$B$4:$GQ$24,COLUMN()-COLUMN($GZ$1)+1,0)) -> 0 | ... HT21: =SUMPRODUCT($B21:$GQ21,INDEX(PLAN_PRODUCCION!$B$4:$GQ$24,COLUMN()-COLUMN($GZ$1)+1,0)) -> 0 | HW21: =DIM_BILL[[#This Row],[Tipo]]
A22: 51TBMF02 | GC22: 1 | GR22: MULTILYTE FRESA KIWI 20 TABS EFER MIX ST | GS22: 2 | GV22: =SUMIF(FACT_A1[cve_prod],DIM_BILL[[#This Row],[CODIGO]],FACT_A1[Existencia]) -> 0 | GW22: =SUMIF(FACT_A2[cve_prod],DIM_BILL[[#This Row],[CODIGO]],FACT_A2[Existencia]) -> 0 | GY22: Cortos + PO's Confirmadas | GZ22: =GV22+GW22+GX22+GZ20-GZ21 -> -7000 | HA22: =GZ22+HA20-HA21 -> -7000 | HB22: =HA22+HB20-HB21 -> -7000 | HC22: =HB22+HC20-HC21 -> -7000 | HD22: =HC22+HD20-HD21 -> -7000 | HE22: =HD22+HE20-HE21 -> -7000 | HF22: =HE22+HF20-HF21 -> -7000 | HG22: =HF22+HG20-HG21 -> -7000 | HH22: =HG22+HH20-HH21 -> -7000 | ... HT22: =HS22+HT20-HT21 -> -7000 | HU22: =COUNTIF(GZ22:HT22,"<0") -> 21 | HW22: =DIM_BILL[[#This Row],[Tipo]]
A23: 51TBML02 | GC23: 1 | GR23: MULTILYTE LIMONADA C/20 TABS EFER MIX ST | GS23: 2 | GV23: =SUMIF(FACT_A1[cve_prod],DIM_BILL[[#This Row],[CODIGO]],FACT_A1[Existencia]) -> 0 | GW23: =SUMIF(FACT_A2[cve_prod],DIM_BILL[[#This Row],[CODIGO]],FACT_A2[Existencia]) -> 0 | GY23: Por Surtir & Parcial | GZ23: =SUMIFS(POs[saldo],POs[cve_prod],DIM_BILL[[#This Row],[CODIGO]],POs[status],$GY23,POs[f_ent],GZ$1) -> 0 | HA23: =SUMIFS(POs[saldo],POs[cve_prod],DIM_BILL[[#This Row],[CODIGO]],POs[status],$GY23,POs[f_ent],HA$1) -> 0 | HB23: =SUMIFS(POs[saldo],POs[cve_prod],DIM_BILL[[#This Row],[CODIGO]],POs[status],$GY23,POs[f_ent],HB$1) -> 0 | HC23: =SUMIFS(POs[saldo],POs[cve_prod],DIM_BILL[[#This Row],[CODIGO]],POs[status],$GY23,POs[f_ent],HC$1) -> 0 | HD23: =SUMIFS(POs[saldo],POs[cve_prod],DIM_BILL[[#This Row],[CODIGO]],POs[status],$GY23,POs[f_ent],HD$1) -> 0 | HE23: =SUMIFS(POs[saldo],POs[cve_prod],DIM_BILL[[#This Row],[CODIGO]],POs[status],$GY23,POs[f_ent],HE$1) -> 0 | HF23: =SUMIFS(POs[saldo],POs[cve_prod],DIM_BILL[[#This Row],[CODIGO]],POs[status],$GY23,POs[Semana],WEEKNUM(HF$1)) -> 0 | HG23: =SUMIFS(POs[saldo],POs[cve_prod],DIM_BILL[[#This Row],[CODIGO]],POs[status],$GY23,POs[Semana],WEEKNUM(HG$1)) -> 0 | HH23: =SUMIFS(POs[saldo],POs[cve_prod],DIM_BILL[[#This Row],[CODIGO]],POs[status],$GY23,POs[Semana],WEEKNUM(HH$1)) -> 0 | HI23: =SUMIFS(POs[saldo],POs[cve_prod],DIM_BILL[[#This Row],[CODIGO]],POs[status],$GY23,POs[Semana],WEEKNUM(HI$1)) -> 0 | HJ23: =SUMIFS(POs[saldo],POs[cve_prod],DIM_BILL[[#This Row],[CODIGO]],POs[status],$GY23,POs[Semana],WEEKNUM(HJ$1)) -> 0 | HK23: =SUMIFS(POs[saldo],POs[cve_prod],DIM_BILL[[#This Row],[CODIGO]],POs[status],$GY23,POs[Semana],WEEKNUM(HK$1)) -> 0 | HL23: =SUMIFS(POs[saldo],POs[cve_prod],DIM_BILL[[#This Row],[CODIGO]],POs[status],$GY23,POs[Semana],WEEKNUM(HL$1)) -> 0 | HM23: =SUMIFS(POs[saldo],POs[cve_prod],DIM_BILL[[#This Row],[CODIGO]],POs[status],$GY23,POs[Semana],WEEKNUM(HM$1)) -> 0 | ... HT23: =SUMIFS(POs[saldo],POs[cve_prod],DIM_BILL[[#This Row],[CODIGO]],POs[status],$GY23,POs[Semana],WEEKNUM(HT$1)) -> 0 | HW23: =DIM_BILL[[#This Row],[Tipo]]
A24: 51TBML02 | GC24: 1 | GR24: MULTILYTE LIMONADA C/20 TABS EFER MIX ST | GS24: 2 | GV24: =SUMIF(FACT_A1[cve_prod],DIM_BILL[[#This Row],[CODIGO]],FACT_A1[Existencia]) -> 0 | GW24: =SUMIF(FACT_A2[cve_prod],DIM_BILL[[#This Row],[CODIGO]],FACT_A2[Existencia]) -> 0 | GY24: Demanda | GZ24: =SUMPRODUCT($B24:$GQ24,INDEX(PLAN_PRODUCCION!$B$4:$GQ$24,COLUMN()-COLUMN($GZ$1)+1,0)) -> 7000 | HA24: =SUMPRODUCT($B24:$GQ24,INDEX(PLAN_PRODUCCION!$B$4:$GQ$24,COLUMN()-COLUMN($GZ$1)+1,0)) -> 0 | HB24: =SUMPRODUCT($B24:$GQ24,INDEX(PLAN_PRODUCCION!$B$4:$GQ$24,COLUMN()-COLUMN($GZ$1)+1,0)) -> 0 | HC24: =SUMPRODUCT($B24:$GQ24,INDEX(PLAN_PRODUCCION!$B$4:$GQ$24,COLUMN()-COLUMN($GZ$1)+1,0)) -> 0 | HD24: =SUMPRODUCT($B24:$GQ24,INDEX(PLAN_PRODUCCION!$B$4:$GQ$24,COLUMN()-COLUMN($GZ$1)+1,0)) -> 0 | HE24: =SUMPRODUCT($B24:$GQ24,INDEX(PLAN_PRODUCCION!$B$4:$GQ$24,COLUMN()-COLUMN($GZ$1)+1,0)) -> 0 | HF24: =SUMPRODUCT($B24:$GQ24,INDEX(PLAN_PRODUCCION!$B$4:$GQ$24,COLUMN()-COLUMN($GZ$1)+1,0)) -> 0 | HG24: =SUMPRODUCT($B24:$GQ24,INDEX(PLAN_PRODUCCION!$B$4:$GQ$24,COLUMN()-COLUMN($GZ$1)+1,0)) -> 0 | ... HT24: =SUMPRODUCT($B24:$GQ24,INDEX(PLAN_PRODUCCION!$B$4:$GQ$24,COLUMN()-COLUMN($GZ$1)+1,0)) -> 0 | HW24: =DIM_BILL[[#This Row],[Tipo]]
A25: 51TBML02 | GC25: 1 | GR25: MULTILYTE LIMONADA C/20 TABS EFER MIX ST | GS25: 2 | GV25: =SUMIF(FACT_A1[cve_prod],DIM_BILL[[#This Row],[CODIGO]],FACT_A1[Existencia]) -> 0 | GW25: =SUMIF(FACT_A2[cve_prod],DIM_BILL[[#This Row],[CODIGO]],FACT_A2[Existencia]) -> 0 | GY25: Cortos + PO's Confirmadas | GZ25: =GV25+GW25+GX25+GZ23-GZ24 -> -7000 | HA25: =GZ25+HA23-HA24 -> -7000 | HB25: =HA25+HB23-HB24 -> -7000 | HC25: =HB25+HC23-HC24 -> -7000 | HD25: =HC25+HD23-HD24 -> -7000 | HE25: =HD25+HE23-HE24 -> -7000 | HF25: =HE25+HF23-HF24 -> -7000 | HG25: =HF25+HG23-HG24 -> -7000 | HH25: =HG25+HH23-HH24 -> -7000 | ... HT25: =HS25+HT23-HT24 -> -7000 | HU25: =COUNTIF(GZ25:HT25,"<0") -> 21 | HW25: =DIM_BILL[[#This Row],[Tipo]]
A26: 51TBMN02 | GC26: 1 | GR26: MULTILYTE NARANJA C/20 TABS EFER MIX ST | GS26: 2 | GV26: =SUMIF(FACT_A1[cve_prod],DIM_BILL[[#This Row],[CODIGO]],FACT_A1[Existencia]) -> 0 | GW26: =SUMIF(FACT_A2[cve_prod],DIM_BILL[[#This Row],[CODIGO]],FACT_A2[Existencia]) -> 0 | GY26: Por Surtir & Parcial | GZ26: =SUMIFS(POs[saldo],POs[cve_prod],DIM_BILL[[#This Row],[CODIGO]],POs[status],$GY26,POs[f_ent],GZ$1) -> 0 | HA26: =SUMIFS(POs[saldo],POs[cve_prod],DIM_BILL[[#This Row],[CODIGO]],POs[status],$GY26,POs[f_ent],HA$1) -> 0 | HB26: =SUMIFS(POs[saldo],POs[cve_prod],DIM_BILL[[#This Row],[CODIGO]],POs[status],$GY26,POs[f_ent],HB$1) -> 0 | HC26: =SUMIFS(POs[saldo],POs[cve_prod],DIM_BILL[[#This Row],[CODIGO]],POs[status],$GY26,POs[f_ent],HC$1) -> 0 | HD26: =SUMIFS(POs[saldo],POs[cve_prod],DIM_BILL[[#This Row],[CODIGO]],POs[status],$GY26,POs[f_ent],HD$1) -> 0 | HE26: =SUMIFS(POs[saldo],POs[cve_prod],DIM_BILL[[#This Row],[CODIGO]],POs[status],$GY26,POs[f_ent],HE$1) -> 0 | HF26: =SUMIFS(POs[saldo],POs[cve_prod],DIM_BILL[[#This Row],[CODIGO]],POs[status],$GY26,POs[Semana],WEEKNUM(HF$1)) -> 0 | HG26: =SUMIFS(POs[saldo],POs[cve_prod],DIM_BILL[[#This Row],[CODIGO]],POs[status],$GY26,POs[Semana],WEEKNUM(HG$1)) -> 0 | HH26: =SUMIFS(POs[saldo],POs[cve_prod],DIM_BILL[[#This Row],[CODIGO]],POs[status],$GY26,POs[Semana],WEEKNUM(HH$1)) -> 0 | HI26: =SUMIFS(POs[saldo],POs[cve_prod],DIM_BILL[[#This Row],[CODIGO]],POs[status],$GY26,POs[Semana],WEEKNUM(HI$1)) -> 0 | HJ26: =SUMIFS(POs[saldo],POs[cve_prod],DIM_BILL[[#This Row],[CODIGO]],POs[status],$GY26,POs[Semana],WEEKNUM(HJ$1)) -> 0 | HK26: =SUMIFS(POs[saldo],POs[cve_prod],DIM_BILL[[#This Row],[CODIGO]],POs[status],$GY26,POs[Semana],WEEKNUM(HK$1)) -> 0 | HL26: =SUMIFS(POs[saldo],POs[cve_prod],DIM_BILL[[#This Row],[CODIGO]],POs[status],$GY26,POs[Semana],WEEKNUM(HL$1)) -> 0 | HM26: =SUMIFS(POs[saldo],POs[cve_prod],DIM_BILL[[#This Row],[CODIGO]],POs[status],$GY26,POs[Semana],WEEKNUM(HM$1)) -> 0 | ... HT26: =SUMIFS(POs[saldo],POs[cve_prod],DIM_BILL[[#This Row],[CODIGO]],POs[status],$GY26,POs[Semana],WEEKNUM(HT$1)) -> 0 | HW26: =DIM_BILL[[#This Row],[Tipo]]
A27: 51TBMN02 | GC27: 1 | GR27: MULTILYTE NARANJA C/20 TABS EFER MIX ST | GS27: 2 | GV27: =SUMIF(FACT_A1[cve_prod],DIM_BILL[[#This Row],[CODIGO]],FACT_A1[Existencia]) -> 0 | GW27: =SUMIF(FACT_A2[cve_prod],DIM_BILL[[#This Row],[CODIGO]],FACT_A2[Existencia]) -> 0 | GY27: Demanda | GZ27: =SUMPRODUCT($B27:$GQ27,INDEX(PLAN_PRODUCCION!$B$4:$GQ$24,COLUMN()-COLUMN($GZ$1)+1,0)) -> 7000 | HA27: =SUMPRODUCT($B27:$GQ27,INDEX(PLAN_PRODUCCION!$B$4:$GQ$24,COLUMN()-COLUMN($GZ$1)+1,0)) -> 0 | HB27: =SUMPRODUCT($B27:$GQ27,INDEX(PLAN_PRODUCCION!$B$4:$GQ$24,COLUMN()-COLUMN($GZ$1)+1,0)) -> 0 | HC27: =SUMPRODUCT($B27:$GQ27,INDEX(PLAN_PRODUCCION!$B$4:$GQ$24,COLUMN()-COLUMN($GZ$1)+1,0)) -> 0 | HD27: =SUMPRODUCT($B27:$GQ27,INDEX(PLAN_PRODUCCION!$B$4:$GQ$24,COLUMN()-COLUMN($GZ$1)+1,0)) -> 0 | HE27: =SUMPRODUCT($B27:$GQ27,INDEX(PLAN_PRODUCCION!$B$4:$GQ$24,COLUMN()-COLUMN($GZ$1)+1,0)) -> 0 | HF27: =SUMPRODUCT($B27:$GQ27,INDEX(PLAN_PRODUCCION!$B$4:$GQ$24,COLUMN()-COLUMN($GZ$1)+1,0)) -> 0 | HG27: =SUMPRODUCT($B27:$GQ27,INDEX(PLAN_PRODUCCION!$B$4:$GQ$24,COLUMN()-COLUMN($GZ$1)+1,0)) -> 0 | ... HT27: =SUMPRODUCT($B27:$GQ27,INDEX(PLAN_PRODUCCION!$B$4:$GQ$24,COLUMN()-COLUMN($GZ$1)+1,0)) -> 0 | HW27: =DIM_BILL[[#This Row],[Tipo]]
A28: 51TBMN02 | GC28: 1 | GR28: MULTILYTE NARANJA C/20 TABS EFER MIX ST | GS28: 2 | GV28: =SUMIF(FACT_A1[cve_prod],DIM_BILL[[#This Row],[CODIGO]],FACT_A1[Existencia]) -> 0 | GW28: =SUMIF(FACT_A2[cve_prod],DIM_BILL[[#This Row],[CODIGO]],FACT_A2[Existencia]) -> 0 | GY28: Cortos + PO's Confirmadas | GZ28: =GV28+GW28+GX28+GZ26-GZ27 -> -7000 | HA28: =GZ28+HA26-HA27 -> -7000 | HB28: =HA28+HB26-HB27 -> -7000 | HC28: =HB28+HC26-HC27 -> -7000 | HD28: =HC28+HD26-HD27 -> -7000 | HE28: =HD28+HE26-HE27 -> -7000 | HF28: =HE28+HF26-HF27 -> -7000 | HG28: =HF28+HG26-HG27 -> -7000 | HH28: =HG28+HH26-HH27 -> -7000 | ... HT28: =HS28+HT26-HT27 -> -7000 | HU28: =COUNTIF(GZ28:HT28,"<0") -> 21 | HW28: =DIM_BILL[[#This Row],[Tipo]]
A29: DES-0032 | BT29: 0.00063454545 | BU29: 0.0011168 | BW29: 0.0011168 | BX29: 0.00063454545 | BY29: 0.0022336 | BZ29: 0.0011168 | CA29: 0.00063454545 | CB29: 0.0022336 | CC29: 0.00093066667 | CD29: 0.002792 | CQ29: 0.0019008 | CT29: 0.0019 | GR29: FOSFATO DICALCICO ANHIDRO | GS29: 1 | GT29: HCQ INGREDIENTES PARA LA INDUSTRIA ALIMENTICIA, S.A. DE C.V. | GU29: MATERIA PRIMA | GV29: =SUMIF(FACT_A1[cve_prod],DIM_BILL[[#This Row],[CODIGO]],FACT_A1[Existencia]) -> 0 | GW29: =SUMIF(FACT_A2[cve_prod],DIM_BILL[[#This Row],[CODIGO]],FACT_A2[Existencia]) -> 39.27902 | GY29: Por Surtir & Parcial | GZ29: =SUMIFS(POs[saldo],POs[cve_prod],DIM_BILL[[#This Row],[CODIGO]],POs[status],$GY29,POs[f_ent],GZ$1) -> 0 | HA29: =SUMIFS(POs[saldo],POs[cve_prod],DIM_BILL[[#This Row],[CODIGO]],POs[status],$GY29,POs[f_ent],HA$1) -> 0 | HB29: =SUMIFS(POs[saldo],POs[cve_prod],DIM_BILL[[#This Row],[CODIGO]],POs[status],$GY29,POs[f_ent],HB$1) -> 0 | HC29: =SUMIFS(POs[saldo],POs[cve_prod],DIM_BILL[[#This Row],[CODIGO]],POs[status],$GY29,POs[f_ent],HC$1) -> 0 | HD29: =SUMIFS(POs[saldo],POs[cve_prod],DIM_BILL[[#This Row],[CODIGO]],POs[status],$GY29,POs[f_ent],HD$1) -> 0 | HE29: =SUMIFS(POs[saldo],POs[cve_prod],DIM_BILL[[#This Row],[CODIGO]],POs[status],$GY29,POs[f_ent],HE$1) -> 0 | HF29: =SUMIFS(POs[saldo],POs[cve_prod],DIM_BILL[[#This Row],[CODIGO]],POs[status],$GY29,POs[Semana],WEEKNUM(HF$1)) -> 0 | HG29: =SUMIFS(POs[saldo],POs[cve_prod],DIM_BILL[[#This Row],[CODIGO]],POs[status],$GY29,POs[Semana],WEEKNUM(HG$1)) -> 0 | HH29: =SUMIFS(POs[saldo],POs[cve_prod],DIM_BILL[[#This Row],[CODIGO]],POs[status],$GY29,POs[Semana],WEEKNUM(HH$1)) -> 0 | HI29: =SUMIFS(POs[saldo],POs[cve_prod],DIM_BILL[[#This Row],[CODIGO]],POs[status],$GY29,POs[Semana],WEEKNUM(HI$1)) -> 0 | HJ29: =SUMIFS(POs[saldo],POs[cve_prod],DIM_BILL[[#This Row],[CODIGO]],POs[status],$GY29,POs[Semana],WEEKNUM(HJ$1)) -> 0 | HK29: =SUMIFS(POs[saldo],POs[cve_prod],DIM_BILL[[#This Row],[CODIGO]],POs[status],$GY29,POs[Semana],WEEKNUM(HK$1)) -> 0 | HL29: =SUMIFS(POs[saldo],POs[cve_prod],DIM_BILL[[#This Row],[CODIGO]],POs[status],$GY29,POs[Semana],WEEKNUM(HL$1)) -> 0 | HM29: =SUMIFS(POs[saldo],POs[cve_prod],DIM_BILL[[#This Row],[CODIGO]],POs[status],$GY29,POs[Semana],WEEKNUM(HM$1)) -> 0 | ... HT29: =SUMIFS(POs[saldo],POs[cve_prod],DIM_BILL[[#This Row],[CODIGO]],POs[status],$GY29,POs[Semana],WEEKNUM(HT$1)) -> 0 | HW29: =DIM_BILL[[#This Row],[Tipo]] -> MATERIA PRIMA
A30: DES-0032 | BT30: 0.00063454545 | BU30: 0.0011168 | BW30: 0.0011168 | BX30: 0.00063454545 | BY30: 0.0022336 | BZ30: 0.0011168 | CA30: 0.00063454545 | CB30: 0.0022336 | CC30: 0.00093066667 | CD30: 0.002792 | CQ30: 0.0019008 | CT30: 0.0019 | GR30: FOSFATO DICALCICO ANHIDRO | GS30: 1 | GT30: HCQ INGREDIENTES PARA LA INDUSTRIA ALIMENTICIA, S.A. DE C.V. | GU30: MATERIA PRIMA | GV30: =SUMIF(FACT_A1[cve_prod],DIM_BILL[[#This Row],[CODIGO]],FACT_A1[Existencia]) -> 0 | GW30: =SUMIF(FACT_A2[cve_prod],DIM_BILL[[#This Row],[CODIGO]],FACT_A2[Existencia]) -> 39.27902 | GY30: Demanda | GZ30: =SUMPRODUCT($B30:$GQ30,INDEX(PLAN_PRODUCCION!$B$4:$GQ$24,COLUMN()-COLUMN($GZ$1)+1,0)) -> 77.3375 | HA30: =SUMPRODUCT($B30:$GQ30,INDEX(PLAN_PRODUCCION!$B$4:$GQ$24,COLUMN()-COLUMN($GZ$1)+1,0)) -> 0 | HB30: =SUMPRODUCT($B30:$GQ30,INDEX(PLAN_PRODUCCION!$B$4:$GQ$24,COLUMN()-COLUMN($GZ$1)+1,0)) -> 0 | HC30: =SUMPRODUCT($B30:$GQ30,INDEX(PLAN_PRODUCCION!$B$4:$GQ$24,COLUMN()-COLUMN($GZ$1)+1,0)) -> 0 | HD30: =SUMPRODUCT($B30:$GQ30,INDEX(PLAN_PRODUCCION!$B$4:$GQ$24,COLUMN()-COLUMN($GZ$1)+1,0)) -> 0 | HE30: =SUMPRODUCT($B30:$GQ30,INDEX(PLAN_PRODUCCION!$B$4:$GQ$24,COLUMN()-COLUMN($GZ$1)+1,0)) -> 0 | HF30: =SUMPRODUCT($B30:$GQ30,INDEX(PLAN_PRODUCCION!$B$4:$GQ$24,COLUMN()-COLUMN($GZ$1)+1,0)) -> 0 | HG30: =SUMPRODUCT($B30:$GQ30,INDEX(PLAN_PRODUCCION!$B$4:$GQ$24,COLUMN()-COLUMN($GZ$1)+1,0)) -> 0 | ... HT30: =SUMPRODUCT($B30:$GQ30,INDEX(PLAN_PRODUCCION!$B$4:$GQ$24,COLUMN()-COLUMN($GZ$1)+1,0)) -> 0 | HW30: =DIM_BILL[[#This Row],[Tipo]] -> MATERIA PRIMA
A31: DES-0032 | BT31: 0.00063454545 | BU31: 0.0011168 | BW31: 0.0011168 | BX31: 0.00063454545 | BY31: 0.0022336 | BZ31: 0.0011168 | CA31: 0.00063454545 | CB31: 0.0022336 | CC31: 0.00093066667 | CD31: 0.002792 | CQ31: 0.0019008 | CT31: 0.0019 | GR31: FOSFATO DICALCICO ANHIDRO | GS31: 1 | GT31: HCQ INGREDIENTES PARA LA INDUSTRIA ALIMENTICIA, S.A. DE C.V. | GU31: MATERIA PRIMA | GV31: =SUMIF(FACT_A1[cve_prod],DIM_BILL[[#This Row],[CODIGO]],FACT_A1[Existencia]) -> 0 | GW31: =SUMIF(FACT_A2[cve_prod],DIM_BILL[[#This Row],[CODIGO]],FACT_A2[Existencia]) -> 39.27902 | GY31: Cortos + PO's Confirmadas | GZ31: =GV31+GW31+GX31+GZ29-GZ30 -> -38.05848 | HA31: =GZ31+HA29-HA30 -> -38.05848 | HB31: =HA31+HB29-HB30 -> -38.05848 | HC31: =HB31+HC29-HC30 -> -38.05848 | HD31: =HC31+HD29-HD30 -> -38.05848 | HE31: =HD31+HE29-HE30 -> -38.05848 | HF31: =HE31+HF29-HF30 -> -38.05848 | HG31: =HF31+HG29-HG30 -> -38.05848 | HH31: =HG31+HH29-HH30 -> -38.05848 | ... HT31: =HS31+HT29-HT30 -> -38.05848 | HU31: =COUNTIF(GZ31:HT31,"<0") -> 21 | HW31: =DIM_BILL[[#This Row],[Tipo]] -> MATERIA PRIMA
A32: M | FH32: 0.78 | FK32: 0.0063333333 | FW32: 0.063333333 | GG32: 0.0018888889 | GR32: MANO DE O. | GS32: 2 | GV32: =SUMIF(FACT_A1[cve_prod],DIM_BILL[[#This Row],[CODIGO]],FACT_A1[Existencia]) -> 0 | GW32: =SUMIF(FACT_A2[cve_prod],DIM_BILL[[#This Row],[CODIGO]],FACT_A2[Existencia]) -> 0 | GY32: Por Surtir & Parcial | GZ32: =SUMIFS(POs[saldo],POs[cve_prod],DIM_BILL[[#This Row],[CODIGO]],POs[status],$GY32,POs[f_ent],GZ$1) -> 0 | HA32: =SUMIFS(POs[saldo],POs[cve_prod],DIM_BILL[[#This Row],[CODIGO]],POs[status],$GY32,POs[f_ent],HA$1) -> 0 | HB32: =SUMIFS(POs[saldo],POs[cve_prod],DIM_BILL[[#This Row],[CODIGO]],POs[status],$GY32,POs[f_ent],HB$1) -> 0 | HC32: =SUMIFS(POs[saldo],POs[cve_prod],DIM_BILL[[#This Row],[CODIGO]],POs[status],$GY32,POs[f_ent],HC$1) -> 0 | HD32: =SUMIFS(POs[saldo],POs[cve_prod],DIM_BILL[[#This Row],[CODIGO]],POs[status],$GY32,POs[f_ent],HD$1) -> 0 | HE32: =SUMIFS(POs[saldo],POs[cve_prod],DIM_BILL[[#This Row],[CODIGO]],POs[status],$GY32,POs[f_ent],HE$1) -> 0 | HF32: =SUMIFS(POs[saldo],POs[cve_prod],DIM_BILL[[#This Row],[CODIGO]],POs[status],$GY32,POs[Semana],WEEKNUM(HF$1)) -> 0 | HG32: =SUMIFS(POs[saldo],POs[cve_prod],DIM_BILL[[#This Row],[CODIGO]],POs[status],$GY32,POs[Semana],WEEKNUM(HG$1)) -> 0 | HH32: =SUMIFS(POs[saldo],POs[cve_prod],DIM_BILL[[#This Row],[CODIGO]],POs[status],$GY32,POs[Semana],WEEKNUM(HH$1)) -> 0 | HI32: =SUMIFS(POs[saldo],POs[cve_prod],DIM_BILL[[#This Row],[CODIGO]],POs[status],$GY32,POs[Semana],WEEKNUM(HI$1)) -> 0 | HJ32: =SUMIFS(POs[saldo],POs[cve_prod],DIM_BILL[[#This Row],[CODIGO]],POs[status],$GY32,POs[Semana],WEEKNUM(HJ$1)) -> 0 | HK32: =SUMIFS(POs[saldo],POs[cve_prod],DIM_BILL[[#This Row],[CODIGO]],POs[status],$GY32,POs[Semana],WEEKNUM(HK$1)) -> 0 | HL32: =SUMIFS(POs[saldo],POs[cve_prod],DIM_BILL[[#This Row],[CODIGO]],POs[status],$GY32,POs[Semana],WEEKNUM(HL$1)) -> 0 | HM32: =SUMIFS(POs[saldo],POs[cve_prod],DIM_BILL[[#This Row],[CODIGO]],POs[status],$GY32,POs[Semana],WEEKNUM(HM$1)) -> 0 | ... HT32: =SUMIFS(POs[saldo],POs[cve_prod],DIM_BILL[[#This Row],[CODIGO]],POs[status],$GY32,POs[Semana],WEEKNUM(HT$1)) -> 0 | HW32: =DIM_BILL[[#This Row],[Tipo]]
A33: M | FH33: 0.78 | FK33: 0.0063333333 | FW33: 0.063333333 | GG33: 0.0018888889 | GR33: MANO DE O. | GS33: 2 | GV33: =SUMIF(FACT_A1[cve_prod],DIM_BILL[[#This Row],[CODIGO]],FACT_A1[Existencia]) -> 0 | GW33: =SUMIF(FACT_A2[cve_prod],DIM_BILL[[#This Row],[CODIGO]],FACT_A2[Existencia]) -> 0 | GY33: Demanda | GZ33: =SUMPRODUCT($B33:$GQ33,INDEX(PLAN_PRODUCCION!$B$4:$GQ$24,COLUMN()-COLUMN($GZ$1)+1,0)) -> 108 | HA33: =SUMPRODUCT($B33:$GQ33,INDEX(PLAN_PRODUCCION!$B$4:$GQ$24,COLUMN()-COLUMN($GZ$1)+1,0)) -> 0 | HB33: =SUMPRODUCT($B33:$GQ33,INDEX(PLAN_PRODUCCION!$B$4:$GQ$24,COLUMN()-COLUMN($GZ$1)+1,0)) -> 0 | HC33: =SUMPRODUCT($B33:$GQ33,INDEX(PLAN_PRODUCCION!$B$4:$GQ$24,COLUMN()-COLUMN($GZ$1)+1,0)) -> 0 | HD33: =SUMPRODUCT($B33:$GQ33,INDEX(PLAN_PRODUCCION!$B$4:$GQ$24,COLUMN()-COLUMN($GZ$1)+1,0)) -> 0 | HE33: =SUMPRODUCT($B33:$GQ33,INDEX(PLAN_PRODUCCION!$B$4:$GQ$24,COLUMN()-COLUMN($GZ$1)+1,0)) -> 0 | HF33: =SUMPRODUCT($B33:$GQ33,INDEX(PLAN_PRODUCCION!$B$4:$GQ$24,COLUMN()-COLUMN($GZ$1)+1,0)) -> 0 | HG33: =SUMPRODUCT($B33:$GQ33,INDEX(PLAN_PRODUCCION!$B$4:$GQ$24,COLUMN()-COLUMN($GZ$1)+1,0)) -> 0 | ... HT33: =SUMPRODUCT($B33:$GQ33,INDEX(PLAN_PRODUCCION!$B$4:$GQ$24,COLUMN()-COLUMN($GZ$1)+1,0)) -> 0 | HW33: =DIM_BILL[[#This Row],[Tipo]]
A34: M | FH34: 0.78 | FK34: 0.0063333333 | FW34: 0.063333333 | GG34: 0.0018888889 | GR34: MANO DE O. | GS34: 2 | GV34: =SUMIF(FACT_A1[cve_prod],DIM_BILL[[#This Row],[CODIGO]],FACT_A1[Existencia]) -> 0 | GW34: =SUMIF(FACT_A2[cve_prod],DIM_BILL[[#This Row],[CODIGO]],FACT_A2[Existencia]) -> 0 | GY34: Cortos + PO's Confirmadas | GZ34: =GV34+GW34+GX34+GZ32-GZ33 -> -108 | HA34: =GZ34+HA32-HA33 -> -108 | HB34: =HA34+HB32-HB33 -> -108 | HC34: =HB34+HC32-HC33 -> -108 | HD34: =HC34+HD32-HD33 -> -108 | HE34: =HD34+HE32-HE33 -> -108 | HF34: =HE34+HF32-HF33 -> -108 | HG34: =HF34+HG32-HG33 -> -108 | HH34: =HG34+HH32-HH33 -> -108 | ... HT34: =HS34+HT32-HT33 -> -108 | HU34: =COUNTIF(GZ34:HT34,"<0") -> 21 | HW34: =DIM_BILL[[#This Row],[Tipo]]
A35: M1CBOM02 | AQ35: 60.034305 | GR35: OMEGA 3, 6 y 9 CÁPSULA BLANDA | GS35: 4 | GT35: BIOCAPS DE MEXICO SA DE CV | GU35: MATERIA PRIMA | GV35: =SUMIF(FACT_A1[cve_prod],DIM_BILL[[#This Row],[CODIGO]],FACT_A1[Existencia]) -> 191371 | GW35: =SUMIF(FACT_A2[cve_prod],DIM_BILL[[#This Row],[CODIGO]],FACT_A2[Existencia]) -> 220000 | GY35: Por Surtir & Parcial | GZ35: =SUMIFS(POs[saldo],POs[cve_prod],DIM_BILL[[#This Row],[CODIGO]],POs[status],$GY35,POs[f_ent],GZ$1) -> 0 | HA35: =SUMIFS(POs[saldo],POs[cve_prod],DIM_BILL[[#This Row],[CODIGO]],POs[status],$GY35,POs[f_ent],HA$1) -> 0 | HB35: =SUMIFS(POs[saldo],POs[cve_prod],DIM_BILL[[#This Row],[CODIGO]],POs[status],$GY35,POs[f_ent],HB$1) -> 0 | HC35: =SUMIFS(POs[saldo],POs[cve_prod],DIM_BILL[[#This Row],[CODIGO]],POs[status],$GY35,POs[f_ent],HC$1) -> 0 | HD35: =SUMIFS(POs[saldo],POs[cve_prod],DIM_BILL[[#This Row],[CODIGO]],POs[status],$GY35,POs[f_ent],HD$1) -> 0 | HE35: =SUMIFS(POs[saldo],POs[cve_prod],DIM_BILL[[#This Row],[CODIGO]],POs[status],$GY35,POs[f_ent],HE$1) -> 0 | HF35: =SUMIFS(POs[saldo],POs[cve_prod],DIM_BILL[[#This Row],[CODIGO]],POs[status],$GY35,POs[Semana],WEEKNUM(HF$1)) -> 0 | HG35: =SUMIFS(POs[saldo],POs[cve_prod],DIM_BILL[[#This Row],[CODIGO]],POs[status],$GY35,POs[Semana],WEEKNUM(HG$1)) -> 0 | HH35: =SUMIFS(POs[saldo],POs[cve_prod],DIM_BILL[[#This Row],[CODIGO]],POs[status],$GY35,POs[Semana],WEEKNUM(HH$1)) -> 350000 | HI35: =SUMIFS(POs[saldo],POs[cve_prod],DIM_BILL[[#This Row],[CODIGO]],POs[status],$GY35,POs[Semana],WEEKNUM(HI$1)) -> 0 | HJ35: =SUMIFS(POs[saldo],POs[cve_prod],DIM_BILL[[#This Row],[CODIGO]],POs[status],$GY35,POs[Semana],WEEKNUM(HJ$1)) -> 0 | HK35: =SUMIFS(POs[saldo],POs[cve_prod],DIM_BILL[[#This Row],[CODIGO]],POs[status],$GY35,POs[Semana],WEEKNUM(HK$1)) -> 0 | HL35: =SUMIFS(POs[saldo],POs[cve_prod],DIM_BILL[[#This Row],[CODIGO]],POs[status],$GY35,POs[Semana],WEEKNUM(HL$1)) -> 0 | HM35: =SUMIFS(POs[saldo],POs[cve_prod],DIM_BILL[[#This Row],[CODIGO]],POs[status],$GY35,POs[Semana],WEEKNUM(HM$1)) -> 0 | ... HT35: =SUMIFS(POs[saldo],POs[cve_prod],DIM_BILL[[#This Row],[CODIGO]],POs[status],$GY35,POs[Semana],WEEKNUM(HT$1)) -> 0 | HW35: =DIM_BILL[[#This Row],[Tipo]] -> MATERIA PRIMA
A36: M1CBOM02 | AQ36: 60.034305 | GR36: OMEGA 3, 6 y 9 CÁPSULA BLANDA | GS36: 4 | GT36: BIOCAPS DE MEXICO SA DE CV | GU36: MATERIA PRIMA | GV36: =SUMIF(FACT_A1[cve_prod],DIM_BILL[[#This Row],[CODIGO]],FACT_A1[Existencia]) -> 191371 | GW36: =SUMIF(FACT_A2[cve_prod],DIM_BILL[[#This Row],[CODIGO]],FACT_A2[Existencia]) -> 220000 | GY36: Demanda | GZ36: =SUMPRODUCT($B36:$GQ36,INDEX(PLAN_PRODUCCION!$B$4:$GQ$24,COLUMN()-COLUMN($GZ$1)+1,0)) -> 289965.69 | HA36: =SUMPRODUCT($B36:$GQ36,INDEX(PLAN_PRODUCCION!$B$4:$GQ$24,COLUMN()-COLUMN($GZ$1)+1,0)) -> 0 | HB36: =SUMPRODUCT($B36:$GQ36,INDEX(PLAN_PRODUCCION!$B$4:$GQ$24,COLUMN()-COLUMN($GZ$1)+1,0)) -> 0 | HC36: =SUMPRODUCT($B36:$GQ36,INDEX(PLAN_PRODUCCION!$B$4:$GQ$24,COLUMN()-COLUMN($GZ$1)+1,0)) -> 0 | HD36: =SUMPRODUCT($B36:$GQ36,INDEX(PLAN_PRODUCCION!$B$4:$GQ$24,COLUMN()-COLUMN($GZ$1)+1,0)) -> 0 | HE36: =SUMPRODUCT($B36:$GQ36,INDEX(PLAN_PRODUCCION!$B$4:$GQ$24,COLUMN()-COLUMN($GZ$1)+1,0)) -> 0 | HF36: =SUMPRODUCT($B36:$GQ36,INDEX(PLAN_PRODUCCION!$B$4:$GQ$24,COLUMN()-COLUMN($GZ$1)+1,0)) -> 0 | HG36: =SUMPRODUCT($B36:$GQ36,INDEX(PLAN_PRODUCCION!$B$4:$GQ$24,COLUMN()-COLUMN($GZ$1)+1,0)) -> 60034.305 | ... HT36: =SUMPRODUCT($B36:$GQ36,INDEX(PLAN_PRODUCCION!$B$4:$GQ$24,COLUMN()-COLUMN($GZ$1)+1,0)) -> 0 | HW36: =DIM_BILL[[#This Row],[Tipo]] -> MATERIA PRIMA
A37: M1CBOM02 | AQ37: 60.034305 | GR37: OMEGA 3, 6 y 9 CÁPSULA BLANDA | GS37: 4 | GT37: BIOCAPS DE MEXICO SA DE CV | GU37: MATERIA PRIMA | GV37: =SUMIF(FACT_A1[cve_prod],DIM_BILL[[#This Row],[CODIGO]],FACT_A1[Existencia]) -> 191371 | GW37: =SUMIF(FACT_A2[cve_prod],DIM_BILL[[#This Row],[CODIGO]],FACT_A2[Existencia]) -> 220000 | GY37: Cortos + PO's Confirmadas | GZ37: =GV37+GW37+GX37+GZ35-GZ36 -> 121405.31 | HA37: =GZ37+HA35-HA36 -> 121405.31 | HB37: =HA37+HB35-HB36 -> 121405.31 | HC37: =HB37+HC35-HC36 -> 121405.31 | HD37: =HC37+HD35-HD36 -> 121405.31 | HE37: =HD37+HE35-HE36 -> 121405.31 | HF37: =HE37+HF35-HF36 -> 121405.31 | HG37: =HF37+HG35-HG36 -> 61371 | HH37: =HG37+HH35-HH36 -> 411371 | ... HT37: =HS37+HT35-HT36 -> 351336.69 | HU37: =COUNTIF(GZ37:HT37,"<0") -> 0 | HV37: Descuadre de inventario y parcial pendiente por ingresar | HW37: =DIM_BILL[[#This Row],[Tipo]] -> MATERIA PRIMA
A38: M1CBOM03 | B38: 60 | AR38: 60.030875 | AS38: 30 | GR38: OMEGA 3 CÁPSULA BLANDA EPA 33/ DHA 22 | GS38: 3 | GT38: LINDY PHARMA | GU38: MATERIA PRIMA | GV38: =SUMIF(FACT_A1[cve_prod],DIM_BILL[[#This Row],[CODIGO]],FACT_A1[Existencia]) -> 0 | GW38: =SUMIF(FACT_A2[cve_prod],DIM_BILL[[#This Row],[CODIGO]],FACT_A2[Existencia]) -> 271166.8 | GY38: Por Surtir & Parcial | GZ38: =SUMIFS(POs[saldo],POs[cve_prod],DIM_BILL[[#This Row],[CODIGO]],POs[status],$GY38,POs[f_ent],GZ$1) -> 0 | HA38: =SUMIFS(POs[saldo],POs[cve_prod],DIM_BILL[[#This Row],[CODIGO]],POs[status],$GY38,POs[f_ent],HA$1) -> 0 | HB38: =SUMIFS(POs[saldo],POs[cve_prod],DIM_BILL[[#This Row],[CODIGO]],POs[status],$GY38,POs[f_ent],HB$1) -> 0 | HC38: =SUMIFS(POs[saldo],POs[cve_prod],DIM_BILL[[#This Row],[CODIGO]],POs[status],$GY38,POs[f_ent],HC$1) -> 0 | HD38: =SUMIFS(POs[saldo],POs[cve_prod],DIM_BILL[[#This Row],[CODIGO]],POs[status],$GY38,POs[f_ent],HD$1) -> 0 | HE38: =SUMIFS(POs[saldo],POs[cve_prod],DIM_BILL[[#This Row],[CODIGO]],POs[status],$GY38,POs[f_ent],HE$1) -> 0 | HF38: =SUMIFS(POs[saldo],POs[cve_prod],DIM_BILL[[#This Row],[CODIGO]],POs[status],$GY38,POs[Semana],WEEKNUM(HF$1)) -> 0 | HG38: =SUMIFS(POs[saldo],POs[cve_prod],DIM_BILL[[#This Row],[CODIGO]],POs[status],$GY38,POs[Semana],WEEKNUM(HG$1)) -> 750000 | HH38: =SUMIFS(POs[saldo],POs[cve_prod],DIM_BILL[[#This Row],[CODIGO]],POs[status],$GY38,POs[Semana],WEEKNUM(HH$1)) -> 0 | HI38: =SUMIFS(POs[saldo],POs[cve_prod],DIM_BILL[[#This Row],[CODIGO]],POs[status],$GY38,POs[Semana],WEEKNUM(HI$1)) -> 0 | HJ38: =SUMIFS(POs[saldo],POs[cve_prod],DIM_BILL[[#This Row],[CODIGO]],POs[status],$GY38,POs[Semana],WEEKNUM(HJ$1)) -> 0 | HK38: =SUMIFS(POs[saldo],POs[cve_prod],DIM_BILL[[#This Row],[CODIGO]],POs[status],$GY38,POs[Semana],WEEKNUM(HK$1)) -> 0 | HL38: =SUMIFS(POs[saldo],POs[cve_prod],DIM_BILL[[#This Row],[CODIGO]],POs[status],$GY38,POs[Semana],WEEKNUM(HL$1)) -> 0 | HM38: =SUMIFS(POs[saldo],POs[cve_prod],DIM_BILL[[#This Row],[CODIGO]],POs[status],$GY38,POs[Semana],WEEKNUM(HM$1)) -> 0 | ... HT38: =SUMIFS(POs[saldo],POs[cve_prod],DIM_BILL[[#This Row],[CODIGO]],POs[status],$GY38,POs[Semana],WEEKNUM(HT$1)) -> 0 | HW38: =DIM_BILL[[#This Row],[Tipo]] -> MATERIA PRIMA
A39: M1CBOM03 | B39: 60 | AR39: 60.030875 | AS39: 30 | GR39: OMEGA 3 CÁPSULA BLANDA EPA 33/ DHA 22 | GS39: 3 | GT39: LINDY PHARMA | GU39: MATERIA PRIMA | GV39: =SUMIF(FACT_A1[cve_prod],DIM_BILL[[#This Row],[CODIGO]],FACT_A1[Existencia]) -> 0 | GW39: =SUMIF(FACT_A2[cve_prod],DIM_BILL[[#This Row],[CODIGO]],FACT_A2[Existencia]) -> 271166.8 | GY39: Demanda | GZ39: =SUMPRODUCT($B39:$GQ39,INDEX(PLAN_PRODUCCION!$B$4:$GQ$24,COLUMN()-COLUMN($GZ$1)+1,0)) -> 694443.97 | HA39: =SUMPRODUCT($B39:$GQ39,INDEX(PLAN_PRODUCCION!$B$4:$GQ$24,COLUMN()-COLUMN($GZ$1)+1,0)) -> 0 | HB39: =SUMPRODUCT($B39:$GQ39,INDEX(PLAN_PRODUCCION!$B$4:$GQ$24,COLUMN()-COLUMN($GZ$1)+1,0)) -> 0 | HC39: =SUMPRODUCT($B39:$GQ39,INDEX(PLAN_PRODUCCION!$B$4:$GQ$24,COLUMN()-COLUMN($GZ$1)+1,0)) -> 0 | HD39: =SUMPRODUCT($B39:$GQ39,INDEX(PLAN_PRODUCCION!$B$4:$GQ$24,COLUMN()-COLUMN($GZ$1)+1,0)) -> 0 | HE39: =SUMPRODUCT($B39:$GQ39,INDEX(PLAN_PRODUCCION!$B$4:$GQ$24,COLUMN()-COLUMN($GZ$1)+1,0)) -> 0 | HF39: =SUMPRODUCT($B39:$GQ39,INDEX(PLAN_PRODUCCION!$B$4:$GQ$24,COLUMN()-COLUMN($GZ$1)+1,0)) -> 0 | HG39: =SUMPRODUCT($B39:$GQ39,INDEX(PLAN_PRODUCCION!$B$4:$GQ$24,COLUMN()-COLUMN($GZ$1)+1,0)) -> 258132.76 | ... HT39: =SUMPRODUCT($B39:$GQ39,INDEX(PLAN_PRODUCCION!$B$4:$GQ$24,COLUMN()-COLUMN($GZ$1)+1,0)) -> 0 | HW39: =DIM_BILL[[#This Row],[Tipo]] -> MATERIA PRIMA
A40: M1CBOM03 | B40: 60 | AR40: 60.030875 | AS40: 30 | GR40: OMEGA 3 CÁPSULA BLANDA EPA 33/ DHA 22 | GS40: 3 | GT40: LINDY PHARMA | GU40: MATERIA PRIMA | GV40: =SUMIF(FACT_A1[cve_prod],DIM_BILL[[#This Row],[CODIGO]],FACT_A1[Existencia]) -> 0 | GW40: =SUMIF(FACT_A2[cve_prod],DIM_BILL[[#This Row],[CODIGO]],FACT_A2[Existencia]) -> 271166.8 | GY40: Cortos + PO's Confirmadas | GZ40: =GV40+GW40+GX40+GZ38-GZ39 -> -423277.17 | HA40: =GZ40+HA38-HA39 -> -423277.17 | HB40: =HA40+HB38-HB39 -> -423277.17 | HC40: =HB40+HC38-HC39 -> -423277.17 | HD40: =HC40+HD38-HD39 -> -423277.17 | HE40: =HD40+HE38-HE39 -> -423277.17 | HF40: =HE40+HF38-HF39 -> -423277.17 | HG40: =HF40+HG38-HG39 -> 68590.066 | HH40: =HG40+HH38-HH39 -> 68590.066 | ... HT40: =HS40+HT38-HT39 -> -651780.43 | HU40: =COUNTIF(GZ40:HT40,"<0") -> 17 | HW40: =DIM_BILL[[#This Row],[Tipo]] -> MATERIA PRIMA
...

Sheet FACT_Explosion
A1: CODIGO | B1: DESCRIPCION | C1: PROVEEDOR | D1: TIPO | E1: LT | F1: INVENTARIO | G1: AGOSTO | H1: SEPTIEMBRE | I1: OCTUBRE | J1: NOVIEMBRE | K1: DICIEMBRE
A2: M1CBOM03 | B2: OMEGA 3 CÁPSULA BLANDA EPA 33/ DHA 22 | C2: LINDY PHARMA | D2: MATERIA PRIMA | E2: =_xlfn.XLOOKUP(FACT_Explosion[[#This Row],[CODIGO]],Proveedores[CODIGO],Proveedores[TIEMPOS DE ENTREGA],0,0,1) -> 3 semana(s) | F2: =_xlfn.XLOOKUP(FACT_Explosion[[#This Row],[CODIGO]],FACT_A2[cve_prod],FACT_A2[Existencia],0,0,1) -> 271166.8 | G2: 714571.7 | H2: 435138.94 | I2: 450138.94 | J2: 375123.5 | K2: 375123.5
A3: MPA-0421 | B3: PEPINO EN POLVO | C3: 2G NUTRITION SAS DE CV | D3: MATERIA PRIMA | E3: =_xlfn.XLOOKUP(FACT_Explosion[[#This Row],[CODIGO]],Proveedores[CODIGO],Proveedores[TIEMPOS DE ENTREGA],0,0,1) -> 3 semana(s) | F3: =_xlfn.XLOOKUP(FACT_Explosion[[#This Row],[CODIGO]],FACT_A2[cve_prod],FACT_A2[Existencia],0,0,1) -> 13.044 | G3: 2.55255 | H3: 1.426425 | I3: 1.35135 | J3: 1.35135 | K3: 1.35135
A4: MEP-0365 | B4: FRASCO BLANCO 150 mL | C4: POLIMEROS ENVASES Y TAPAS TAPATIOS | D4: MATERIAL DE EMPAQUE | E4: =_xlfn.XLOOKUP(FACT_Explosion[[#This Row],[CODIGO]],Proveedores[CODIGO],Proveedores[TIEMPOS DE ENTREGA],0,0,1) -> 3 semnas | F4: =_xlfn.XLOOKUP(FACT_Explosion[[#This Row],[CODIGO]],FACT_A2[cve_prod],FACT_A2[Existencia],0,0,1) -> 24480 | G4: 17932.74 | H4: 14687 | I4: 14687 | J4: 9437 | K4: 9437
A5: MPD-0093 | B5: COLOR CARAMELO 605 polvo | C5: ADITIVES & COLORS S.A. DE C.V. | D5: MATERIA PRIMA | E5: =_xlfn.XLOOKUP(FACT_Explosion[[#This Row],[CODIGO]],Proveedores[CODIGO],Proveedores[TIEMPOS DE ENTREGA],0,0,1) -> 0 | F5: =_xlfn.XLOOKUP(FACT_Explosion[[#This Row],[CODIGO]],FACT_A2[cve_prod],FACT_A2[Existencia],0,0,1) -> 0 | G5: 0 | H5: 0 | I5: 0 | J5: 0 | K5: 0
